Workbook
Name Division: '[1]Not Available'!$B$2:$B$7
Name Division: 'Not Available'!$B$2:$B$7
Name Status: '[1]Not Available'!$B$10:$B$13
Name Status: 'Not Available'!$B$10:$B$13
Name Status: 'Not Available'!$B$10:$B$13

Sheet 説明
A2: ① | B2: 案件．要員情報シートについて
B3: ▲今月のため対応された各案件、プロジェクト管理と他のテストの計画と実績人間を報告することです。 | K3: ※ | L3: メモ
B4: 列名の説明 | C4: 列名 | D4: 内容 | L4: 今週⇒ | M4: 「先週の定例会の日から今週の水曜日までのカウント」
C5: No.列 | D5: 連番 | L5: 来週⇒ | M5: 「今週の定例会の日から来週の水曜日までのカウント」
C6: ステータス | D6: 案件のステータス「未着手、進行中、レビュー待ち、完了」
C7: 区分 | D7: 案件のカテゴリー | L7: ・11月の計画工数の作成方法の説明
C8: DIR 担当 | D8: 案件依頼しているDIR担当者名 | L8: ・11月の計画工数と実績工数の差異の理由
C9: 案件管理コード（DAT) | D9: DAT側でのWBS管理コード | L9: ・12月の計画工数（案件毎の内訳情報も）および過不足工数の説明
C10: 案件管理コード（DIR) | D10: DIR側からの管理コード
C11: 案件 | D11: 今週中対応された案件名
C12: 備考 | D12: リマーク
J14: http://w3ttsvn10/svn/webbroker3_pr/ミャンマーDAT/30_見積り依頼/オンライン開発(2022年9月~2023年2月)についての見積書.xlsx
B15: 案件の計画工数作成方法の説明 | C15: 案件名 | D15: 計画工数作成方法
C16: 定型案件 | D16: WBSを参考し、案件の範囲とメンバーのスキルに依存して作成しています。
C17: (全社)脆弱性対応（2022年）_パス・トラバーサル対応 | D17: ◆他のプロジェクトにはFASE Formを提出して対応するプロジェクトがあります。しかし、WB4にはありません。プロジェクトの計画をPMが上記のことなどを向けて作成しています。
D18: ◆「(全社)脆弱性対応（2022年）_パス・トラバーサル対応」は徳田様が9月から12月まで各月に４人間として企画しました。
D19: ◆DIRと月次会議後には、サービス機能テストもする可能性がありますので、イェさんが２月まで各月に４人間として企画しました。 (9月~2月)の計画人間⇒25.18 各月の計画人間 ⇒ 4.19 (25.18/6)
B21: 計画工数と実績工数の差異の理由 | C21: 案件名 | D21: 理由
C22: 定型案件と (全社)脆弱性対応（2022年）_パス・トラバーサル対応 | D22: ◆DIRから計画を立っていないし、PMが自分で計画したので異なりました。
D23: ◆仕事がありますが、様々な理由で (エラーが発生など)停止しているので異なりました。 ◆仕事が止まる時、メンバーのスキルアップのため研修しています。
B25: ▲DATメンバーが対応しているプロジェクト管理タスクは６つあります。
B27: プロジェクト管理の計画工数作成方法の説明 | C27: タスク名 | D27: 計画工数作成方法
C28: DATチーム会議 | D28: ◆毎日30分(0.5 hr)かかります。 ◆全メンバーが出席しています。 ◆一人⇒(0.5 x Working Day)
C29: DIRとの定例会 | D29: ◆毎週1時間かかります。 ◆全メンバーが出席しています。 ◆一人⇒(１ x week count of a month)
C30: 日次報告書 | D30: ◆DATの社内システム(WHM)とThincの日次報告書に報告記入する時間です。 ◆毎日30分(0.5 hr)かかります。 ◆全メンバーがやっています。 ◆一人⇒(0.5 x Working Day)
C31: 週次報告 | D31: ◆毎週の水曜日DIRへ送信する週次報告作成時間と毎週の金曜日DAT管理人送信する週次報告作成時間 ◆毎週３時間かかります。 ◆PMだけやっています。 ◆一人⇒(0.5 x Working Day)
C32: プロジェクト管理、メール送受信、WBS管理、Redmine管理 | D32: ◆メール送受信時間、WBS作成時間、Redmine管理時間と他の報告作成時間です。 ◆毎日PMは３時間、二人のリーダーは30分かかる。 ◆(3 x Working Day)+(0.5 x Working Day)+(0.5 x Working Day)
C33: メンバーサポート | D33: ◆PMとリーダーが他のメンバーにサポートする時間です。 ◆毎日PMと二人のリーダーは1時間かかる。 ◆(1 x Working Day)+(1 x Working Day)+(1 x Working Day)
B35: 計画工数と実績工数の差異の理由 | C35: 案件名 | D35: 理由
C36: DATチーム会議 | D36: いつものは計画と実績が合っています。
C37: DIRとの定例会 | D37: 計画は1時間ですが、実際は30分以下かかるので 異なりました。
C38: 日次報告書 | D38: いつものは計画と実績が合っています。
C39: 週次報告 | D39: 計画を記入していますが、実績は計算する時には下記のプロジェクト管理テクストに追加して計算しています。 そして、週次報告の実績は'0'になっています。
C40: プロジェクト管理、メール送受信、WBS管理、Redmine管理 | D40: ◆毎日PMのため３時間として予定されていますが、週次報告作成時間を追加し、他の管理タスクがあるため計画と実績が異なります。 ◆毎日二人のリーダーのため30分として予定されていますが、管理タクスがない日もあるので計画と実績が異なります。
C41: メンバーサポート | D41: メンバーはサポートが不要な日もあるので計画と実績が異なります。
B43: ▲その他のタクスには案件と管理以外のタクス例えばJinwa研修やDAT社内作業などのタクスです。
B45: プロジェクト管理の計画工数作成方法の説明 | C45: タスク名 | D45: 計画工数作成方法
C46: WB4 Internal Training | D46: 新入社員がいる月には計画を作成しています。 今は新入社員がいないので計画は０になりました。
C47: JINWA Training(Class Hours) | D47: DATの社内報告書の計画時間と合わせるため、計画が０になりました。
C48: JINWA Training(Practicals) | D48: ◆メンバー４人が毎日3時間対応しています。 ◆一人⇒(３x Working Day)
...

Sheet 案件．要員情報まとめ
A1: 案件．要員情報 | S1: Total Member -7 | W1: Contract Member - 5
S2: FOC Member - 2
A3: ■案件
A4: No. | B4: ステータス | C4: 区分 | D4: DIR 担当 | E4: 案件管理コード（DAT) | F4: 案件管理コード（DIR) | G4: 案件 | H4: 計画 (DIR) | I4: 計画 (DAT) | J4: 実績 | K4: 着手日 | L4: 完了日 | M4: 備考/理由 | N4: 工数（人月）
O5: 4月 | P5: 5月 | Q5: 6月 | R5: 7月 | S5: 8月 | T5: 9月 | U5: 10月 | V5: 11月 | W5: 12月 | X5: 1月 | Y5: 2月 | Z5: 3月
A6: 1 | B6: 着手中 | C6: その他 | D6: 飯田 | E6: BW1 | F6: A5207110 | G6: 【案件依頼】ビルド作業を対応 | N6: 計画 | O6: =SUM('案件．要員情報'!O7:X7) -> 0.7 | P6: =SUM('案件．要員情報'!Y7:AH7) -> 0.44444444 | Q6: =SUM('案件．要員情報'!AI7:AR7) -> 0.39365079 | R6: =SUM('案件．要員情報'!AS7:BB7) -> 0.42424242 | S6: =SUM('案件．要員情報'!BC7:BL7) -> 0.66666667 | T6: =SUM('案件．要員情報'!BM7:BV7) -> 0.42424242 | U6: =SUM('案件．要員情報'!BW7:CF7) -> 0.4 | V6: =SUM('案件．要員情報'!CG7:CP7) -> 0.2962963 | W6: =SUM('案件．要員情報'!CQ7:CW7) -> 0.23333333 | X6: =SUM('案件．要員情報'!CX7:DD7) -> 0.28571429 | Y6: =SUM('案件．要員情報'!DE7:DK7) -> 0.47058824 | Z6: =SUM('案件．要員情報'!DL7:DS7) -> 0 | AA6: =SUM(O6:Z6) -> 4.7391789
N7: 実績 | O7: =SUM('案件．要員情報'!O8:X8) -> 0.64583333 | P7: =SUM('案件．要員情報'!Y8:AH8) -> 0.4031746 | Q7: =SUM('案件．要員情報'!AI8:AR8) -> 0.37777778 | R7: =SUM('案件．要員情報'!AS8:BB8) -> 0.38787879 | S7: =SUM('案件．要員情報'!BC8:BL8) -> 0.66031746 | T7: =SUM('案件．要員情報'!BM8:BV8) -> 0.36666667 | U7: =SUM('案件．要員情報'!BW8:CF8) -> 0.39666667 | V7: =SUM('案件．要員情報'!CG8:CP8) -> 0.21851852 | W7: =SUM('案件．要員情報'!CQ8:CW8) -> 0.21333333 | X7: =SUM('案件．要員情報'!CX8:DD8) -> 0.26349206 | Y7: =SUM('案件．要員情報'!DE8:DK8) -> 0.24313725 | Z7: =SUM('案件．要員情報'!DL8:DS8) -> 0 | AA7: =SUM(O7:Z7) -> 4.1767965
A8: 2 | B8: 完了 | C8: その他 | D8: 坂野 | E8: PL6 | F8: PBxxxxxxxx | G8: 【PLATE】対面WEB_初期フォーカス改善対応 | N8: 計画 | O8: =SUM('案件．要員情報'!O9:X9) -> 0 | P8: =SUM('案件．要員情報'!Y9:AH9) -> 0 | Q8: =SUM('案件．要員情報'!AI9:AR9) -> 0 | R8: =SUM('案件．要員情報'!AS9:BB9) -> 0 | S8: =SUM('案件．要員情報'!BC9:BL9) -> 0 | T8: =SUM('案件．要員情報'!BM9:BV9) -> 0 | U8: =SUM('案件．要員情報'!BW9:CF9) -> 0 | V8: =SUM('案件．要員情報'!CG9:CP9) -> 0 | W8: =SUM('案件．要員情報'!CQ9:CW9) -> 0 | X8: =SUM('案件．要員情報'!CX9:DD9) -> 0 | Y8: =SUM('案件．要員情報'!DE9:DK9) -> 0 | Z8: =SUM('案件．要員情報'!DL9:DS9) -> 0 | AA8: =SUM(O8:Z8) -> 0
N9: 実績 | O9: =SUM('案件．要員情報'!O10:X10) -> 0 | P9: =SUM('案件．要員情報'!Y10:AH10) -> 0 | Q9: =SUM('案件．要員情報'!AI10:AR10) -> 0 | R9: =SUM('案件．要員情報'!AS10:BB10) -> 0 | S9: =SUM('案件．要員情報'!BC10:BL10) -> 0 | T9: =SUM('案件．要員情報'!BM10:BV10) -> 0 | U9: =SUM('案件．要員情報'!BW10:CF10) -> 0 | V9: =SUM('案件．要員情報'!CG10:CP10) -> 0 | W9: =SUM('案件．要員情報'!CQ10:CW10) -> 0 | X9: =SUM('案件．要員情報'!CX10:DD10) -> 0 | Y9: =SUM('案件．要員情報'!DE10:DK10) -> 0 | Z9: =SUM('案件．要員情報'!DL10:DS10) -> 0 | AA9: =SUM(O9:Z9) -> 0
A10: 3 | B10: 完了 | C10: その他 | D10: 山本 | E10: WA2 | G10: 【開発依頼】作業の自動化_UATヘルスチェック | N10: 計画 | O10: =SUM('案件．要員情報'!O11:X11) -> 1.3083333 | P10: =SUM('案件．要員情報'!Y11:AH11) -> 1.968254 | Q10: =SUM('案件．要員情報'!AI11:AR11) -> 0.019047619 | R10: =SUM('案件．要員情報'!AS11:BB11) -> 0.45454545 | S10: =SUM('案件．要員情報'!BC11:BL11) -> 0.28571429 | T10: =SUM('案件．要員情報'!BM11:BV11) -> 0.60606061 | U10: =SUM('案件．要員情報'!BW11:CF11) -> 0.3 | V10: =SUM('案件．要員情報'!CG11:CP11) -> 0 | W10: =SUM('案件．要員情報'!CQ11:CW11) -> 0 | X10: =SUM('案件．要員情報'!CX11:DD11) -> 0 | Y10: =SUM('案件．要員情報'!DE11:DK11) -> 0 | Z10: =SUM('案件．要員情報'!DL11:DS11) -> 0 | AA10: =SUM(O10:Z10) -> 4.9419553
N11: 実績 | O11: =SUM('案件．要員情報'!O12:X12) -> 1.2708333 | P11: =SUM('案件．要員情報'!Y12:AH12) -> 1.9492063 | Q11: =SUM('案件．要員情報'!AI12:AR12) -> 0.015873016 | R11: =SUM('案件．要員情報'!AS12:BB12) -> 0.43636364 | S11: =SUM('案件．要員情報'!BC12:BL12) -> 0.26031746 | T11: =SUM('案件．要員情報'!BM12:BV12) -> 0.61818182 | U11: =SUM('案件．要員情報'!BW12:CF12) -> 0.28666667 | V11: =SUM('案件．要員情報'!CG12:CP12) -> 0 | W11: =SUM('案件．要員情報'!CQ12:CW12) -> 0 | X11: =SUM('案件．要員情報'!CX12:DD12) -> 0 | Y11: =SUM('案件．要員情報'!DE12:DK12) -> 0 | Z11: =SUM('案件．要員情報'!DL12:DS12) -> 0 | AA11: =SUM(O11:Z11) -> 4.8374423
A12: 4 | B12: 完了 | C12: 定型 | D12: 山本 | E12: F180 | F12: PB00201841 | G12: 【定型】定時定額の注文画面での文言追加 | N12: 計画 | O12: =SUM('案件．要員情報'!O13:X13) -> 0.15 | P12: =SUM('案件．要員情報'!Y13:AH13) -> 0 | Q12: =SUM('案件．要員情報'!AI13:AR13) -> 0 | R12: =SUM('案件．要員情報'!AS13:BB13) -> 0 | S12: =SUM('案件．要員情報'!BC13:BL13) -> 0 | T12: =SUM('案件．要員情報'!BM13:BV13) -> 0 | U12: =SUM('案件．要員情報'!BW13:CF13) -> 0 | V12: =SUM('案件．要員情報'!CG13:CP13) -> 0 | W12: =SUM('案件．要員情報'!CQ13:CW13) -> 0 | X12: =SUM('案件．要員情報'!CX13:DD13) -> 0 | Y12: =SUM('案件．要員情報'!DE13:DK13) -> 0 | Z12: =SUM('案件．要員情報'!DL13:DS13) -> 0 | AA12: =SUM(O12:Z12) -> 0.15
N13: 実績 | O13: =SUM('案件．要員情報'!O14:X14) -> 0.14166667 | P13: =SUM('案件．要員情報'!Y14:AH14) -> 0 | Q13: =SUM('案件．要員情報'!AI14:AR14) -> 0 | R13: =SUM('案件．要員情報'!AS14:BB14) -> 0 | S13: =SUM('案件．要員情報'!BC14:BL14) -> 0 | T13: =SUM('案件．要員情報'!BM14:BV14) -> 0 | U13: =SUM('案件．要員情報'!BW14:CF14) -> 0 | V13: =SUM('案件．要員情報'!CG14:CP14) -> 0 | W13: =SUM('案件．要員情報'!CQ14:CW14) -> 0 | X13: =SUM('案件．要員情報'!CX14:DD14) -> 0 | Y13: =SUM('案件．要員情報'!DE14:DK14) -> 0 | Z13: =SUM('案件．要員情報'!DL14:DS14) -> 0 | AA13: =SUM(O13:Z13) -> 0.14166667
A14: 5 | B14: 完了 | C14: 定型 | D14: 山田 | E14: F181 | F14: PB00201845 | G14: 【定型】CFDサービス終了に伴う画面修正 | N14: 計画 | O14: =SUM('案件．要員情報'!O15:X15) -> 0.29166667 | P14: =SUM('案件．要員情報'!Y15:AH15) -> 0 | Q14: =SUM('案件．要員情報'!AI15:AR15) -> 0 | R14: =SUM('案件．要員情報'!AS15:BB15) -> 0 | S14: =SUM('案件．要員情報'!BC15:BL15) -> 0 | T14: =SUM('案件．要員情報'!BM15:BV15) -> 0 | U14: =SUM('案件．要員情報'!BW15:CF15) -> 0 | V14: =SUM('案件．要員情報'!CG15:CP15) -> 0 | W14: =SUM('案件．要員情報'!CQ15:CW15) -> 0 | X14: =SUM('案件．要員情報'!CX15:DD15) -> 0 | Y14: =SUM('案件．要員情報'!DE15:DK15) -> 0 | Z14: =SUM('案件．要員情報'!DL15:DS15) -> 0 | AA14: =SUM(O14:Z14) -> 0.29166667
N15: 実績 | O15: =SUM('案件．要員情報'!O16:X16) -> 0.28333333 | P15: =SUM('案件．要員情報'!Y16:AH16) -> 0 | Q15: =SUM('案件．要員情報'!AI16:AR16) -> 0 | R15: =SUM('案件．要員情報'!AS16:BB16) -> 0 | S15: =SUM('案件．要員情報'!BC16:BL16) -> 0 | T15: =SUM('案件．要員情報'!BM16:BV16) -> 0 | U15: =SUM('案件．要員情報'!BW16:CF16) -> 0 | V15: =SUM('案件．要員情報'!CG16:CP16) -> 0 | W15: =SUM('案件．要員情報'!CQ16:CW16) -> 0 | X15: =SUM('案件．要員情報'!CX16:DD16) -> 0 | Y15: =SUM('案件．要員情報'!DE16:DK16) -> 0 | Z15: =SUM('案件．要員情報'!DL16:DS16) -> 0 | AA15: =SUM(O15:Z15) -> 0.28333333
A16: 6 | B16: 完了 | C16: 定型 | D16: 山田 | E16: F182 | F16: PB00201860 | G16: 【定型】WB4ログイン画面ロゴ画像の変更 | N16: 計画 | O16: =SUM('案件．要員情報'!O17:X17) -> 0.79166667 | P16: =SUM('案件．要員情報'!Y17:AH17) -> 0 | Q16: =SUM('案件．要員情報'!AI17:AR17) -> 0 | R16: =SUM('案件．要員情報'!AS17:BB17) -> 0 | S16: =SUM('案件．要員情報'!BC17:BL17) -> 0 | T16: =SUM('案件．要員情報'!BM17:BV17) -> 0 | U16: =SUM('案件．要員情報'!BW17:CF17) -> 0 | V16: =SUM('案件．要員情報'!CG17:CP17) -> 0 | W16: =SUM('案件．要員情報'!CQ17:CW17) -> 0 | X16: =SUM('案件．要員情報'!CX17:DD17) -> 0 | Y16: =SUM('案件．要員情報'!DE17:DK17) -> 0 | Z16: =SUM('案件．要員情報'!DL17:DS17) -> 0 | AA16: =SUM(O16:Z16) -> 0.79166667
N17: 実績 | O17: =SUM('案件．要員情報'!O18:X18) -> 0.77916667 | P17: =SUM('案件．要員情報'!Y18:AH18) -> 0 | Q17: =SUM('案件．要員情報'!AI18:AR18) -> 0 | R17: =SUM('案件．要員情報'!AS18:BB18) -> 0 | S17: =SUM('案件．要員情報'!BC18:BL18) -> 0 | T17: =SUM('案件．要員情報'!BM18:BV18) -> 0 | U17: =SUM('案件．要員情報'!BW18:CF18) -> 0 | V17: =SUM('案件．要員情報'!CG18:CP18) -> 0 | W17: =SUM('案件．要員情報'!CQ18:CW18) -> 0 | X17: =SUM('案件．要員情報'!CX18:DD18) -> 0 | Y17: =SUM('案件．要員情報'!DE18:DK18) -> 0 | Z17: =SUM('案件．要員情報'!DL18:DS18) -> 0 | AA17: =SUM(O17:Z17) -> 0.77916667
A18: 7 | B18: 完了 | C18: その他 | D18: 寺澤 | E18: MSC1 | G18: 【MSC】画面設計書最新化対応のお願い | N18: 計画 | O18: =SUM('案件．要員情報'!O19:X19) -> 0.70833333 | P18: =SUM('案件．要員情報'!Y19:AH19) -> 0 | Q18: =SUM('案件．要員情報'!AI19:AR19) -> 0 | R18: =SUM('案件．要員情報'!AS19:BB19) -> 0 | S18: =SUM('案件．要員情報'!BC19:BL19) -> 0 | T18: =SUM('案件．要員情報'!BM19:BV19) -> 0 | U18: =SUM('案件．要員情報'!BW19:CF19) -> 0 | V18: =SUM('案件．要員情報'!CG19:CP19) -> 0 | W18: =SUM('案件．要員情報'!CQ19:CW19) -> 0 | X18: =SUM('案件．要員情報'!CX19:DD19) -> 0 | Y18: =SUM('案件．要員情報'!DE19:DK19) -> 0 | Z18: =SUM('案件．要員情報'!DL19:DS19) -> 0 | AA18: =SUM(O18:Z18) -> 0.70833333
N19: 実績 | O19: =SUM('案件．要員情報'!O20:X20) -> 0.69583333 | P19: =SUM('案件．要員情報'!Y20:AH20) -> 0 | Q19: =SUM('案件．要員情報'!AI20:AR20) -> 0 | R19: =SUM('案件．要員情報'!AS20:BB20) -> 0 | S19: =SUM('案件．要員情報'!BC20:BL20) -> 0 | T19: =SUM('案件．要員情報'!BM20:BV20) -> 0 | U19: =SUM('案件．要員情報'!BW20:CF20) -> 0 | V19: =SUM('案件．要員情報'!CG20:CP20) -> 0 | W19: =SUM('案件．要員情報'!CQ20:CW20) -> 0 | X19: =SUM('案件．要員情報'!CX20:DD20) -> 0 | Y19: =SUM('案件．要員情報'!DE20:DK20) -> 0 | Z19: =SUM('案件．要員情報'!DL20:DS20) -> 0 | AA19: =SUM(O19:Z19) -> 0.69583333
A20: 8 | B20: 完了 | C20: その他 | D20: 田中 | E20: AH24 | G20: 【案件依頼】【ツール開発】シェルが稼働しているジョブネットの一覧作成 | N20: 計画 | O20: =SUM('案件．要員情報'!O21:X21) -> 1.75 | P20: =SUM('案件．要員情報'!Y21:AH21) -> 1.7142857 | Q20: =SUM('案件．要員情報'!AI21:AR21) -> 0 | R20: =SUM('案件．要員情報'!AS21:BB21) -> 0 | S20: =SUM('案件．要員情報'!BC21:BL21) -> 0 | T20: =SUM('案件．要員情報'!BM21:BV21) -> 0 | U20: =SUM('案件．要員情報'!BW21:CF21) -> 0 | V20: =SUM('案件．要員情報'!CG21:CP21) -> 0 | W20: =SUM('案件．要員情報'!CQ21:CW21) -> 0 | X20: =SUM('案件．要員情報'!CX21:DD21) -> 0 | Y20: =SUM('案件．要員情報'!DE21:DK21) -> 0 | Z20: =SUM('案件．要員情報'!DL21:DS21) -> 0 | AA20: =SUM(O20:Z20) -> 3.4642857
N21: 実績 | O21: =SUM('案件．要員情報'!O22:X22) -> 1.7416667 | P21: =SUM('案件．要員情報'!Y22:AH22) -> 1.6825397 | Q21: =SUM('案件．要員情報'!AI22:AR22) -> 0 | R21: =SUM('案件．要員情報'!AS22:BB22) -> 0 | S21: =SUM('案件．要員情報'!BC22:BL22) -> 0 | T21: =SUM('案件．要員情報'!BM22:BV22) -> 0 | U21: =SUM('案件．要員情報'!BW22:CF22) -> 0 | V21: =SUM('案件．要員情報'!CG22:CP22) -> 0 | W21: =SUM('案件．要員情報'!CQ22:CW22) -> 0 | X21: =SUM('案件．要員情報'!CX22:DD22) -> 0 | Y21: =SUM('案件．要員情報'!DE22:DK22) -> 0 | Z21: =SUM('案件．要員情報'!DL22:DS22) -> 0 | AA21: =SUM(O21:Z21) -> 3.4242063
A22: 9 | B22: 完了 | C22: その他 | D22: 田中 | E22: AH26 | G22: 【ツール開発】WB4結合環境の状況リスト一覧の作成 | N22: 計画 | O22: =SUM('案件．要員情報'!O23:X23) -> 0.91666667 | P22: =SUM('案件．要員情報'!Y23:AH23) -> 0.095238095 | Q22: =SUM('案件．要員情報'!AI23:AR23) -> 0 | R22: =SUM('案件．要員情報'!AS23:BB23) -> 0 | S22: =SUM('案件．要員情報'!BC23:BL23) -> 0 | T22: =SUM('案件．要員情報'!BM23:BV23) -> 0 | U22: =SUM('案件．要員情報'!BW23:CF23) -> 0 | V22: =SUM('案件．要員情報'!CG23:CP23) -> 0 | W22: =SUM('案件．要員情報'!CQ23:CW23) -> 0 | X22: =SUM('案件．要員情報'!CX23:DD23) -> 0 | Y22: =SUM('案件．要員情報'!DE23:DK23) -> 0 | Z22: =SUM('案件．要員情報'!DL23:DS23) -> 0 | AA22: =SUM(O22:Z22) -> 1.0119048
N23: 実績 | O23: =SUM('案件．要員情報'!O24:X24) -> 0.85 | P23: =SUM('案件．要員情報'!Y24:AH24) -> 0.082539683 | Q23: =SUM('案件．要員情報'!AI24:AR24) -> 0 | R23: =SUM('案件．要員情報'!AS24:BB24) -> 0 | S23: =SUM('案件．要員情報'!BC24:BL24) -> 0 | T23: =SUM('案件．要員情報'!BM24:BV24) -> 0 | U23: =SUM('案件．要員情報'!BW24:CF24) -> 0 | V23: =SUM('案件．要員情報'!CG24:CP24) -> 0 | W23: =SUM('案件．要員情報'!CQ24:CW24) -> 0 | X23: =SUM('案件．要員情報'!CX24:DD24) -> 0 | Y23: =SUM('案件．要員情報'!DE24:DK24) -> 0 | Z23: =SUM('案件．要員情報'!DL24:DS24) -> 0 | AA23: =SUM(O23:Z23) -> 0.93253968
A24: 10 | B24: 完了 | C24: 定型 | D24: 谷口 | E24: F183 | F24: PB00201788 | G24: 【定型】(53)820部店の対面WEB利用 | N24: 計画 | O24: =SUM('案件．要員情報'!O25:X25) -> 0.16666667 | P24: =SUM('案件．要員情報'!Y25:AH25) -> 0.057142857 | Q24: =SUM('案件．要員情報'!AI25:AR25) -> 0 | R24: =SUM('案件．要員情報'!AS25:BB25) -> 0 | S24: =SUM('案件．要員情報'!BC25:BL25) -> 0 | T24: =SUM('案件．要員情報'!BM25:BV25) -> 0 | U24: =SUM('案件．要員情報'!BW25:CF25) -> 0 | V24: =SUM('案件．要員情報'!CG25:CP25) -> 0 | W24: =SUM('案件．要員情報'!CQ25:CW25) -> 0 | X24: =SUM('案件．要員情報'!CX25:DD25) -> 0 | Y24: =SUM('案件．要員情報'!DE25:DK25) -> 0 | Z24: =SUM('案件．要員情報'!DL25:DS25) -> 0 | AA24: =SUM(O24:Z24) -> 0.22380952
N25: 実績 | O25: =SUM('案件．要員情報'!O26:X26) -> 0.15 | P25: =SUM('案件．要員情報'!Y26:AH26) -> 0.050793651 | Q25: =SUM('案件．要員情報'!AI26:AR26) -> 0 | R25: =SUM('案件．要員情報'!AS26:BB26) -> 0 | S25: =SUM('案件．要員情報'!BC26:BL26) -> 0 | T25: =SUM('案件．要員情報'!BM26:BV26) -> 0 | U25: =SUM('案件．要員情報'!BW26:CF26) -> 0 | V25: =SUM('案件．要員情報'!CG26:CP26) -> 0 | W25: =SUM('案件．要員情報'!CQ26:CW26) -> 0 | X25: =SUM('案件．要員情報'!CX26:DD26) -> 0 | Y25: =SUM('案件．要員情報'!DE26:DK26) -> 0 | Z25: =SUM('案件．要員情報'!DL26:DS26) -> 0 | AA25: =SUM(O25:Z25) -> 0.20079365
A26: 11 | B26: 完了 | C26: 定型 | D26: 邵 | E26: F184 | F26: PB00201870 | G26: 【定型】（信用）担保処分に関する文言変更 | N26: 計画 | O26: =SUM('案件．要員情報'!O27:X27) -> 0.55 | P26: =SUM('案件．要員情報'!Y27:AH27) -> 0.012698413 | Q26: =SUM('案件．要員情報'!AI27:AR27) -> 0 | R26: =SUM('案件．要員情報'!AS27:BB27) -> 0 | S26: =SUM('案件．要員情報'!BC27:BL27) -> 0 | T26: =SUM('案件．要員情報'!BM27:BV27) -> 0 | U26: =SUM('案件．要員情報'!BW27:CF27) -> 0 | V26: =SUM('案件．要員情報'!CG27:CP27) -> 0 | W26: =SUM('案件．要員情報'!CQ27:CW27) -> 0 | X26: =SUM('案件．要員情報'!CX27:DD27) -> 0 | Y26: =SUM('案件．要員情報'!DE27:DK27) -> 0 | Z26: =SUM('案件．要員情報'!DL27:DS27) -> 0 | AA26: =SUM(O26:Z26) -> 0.56269841
N27: 実績 | O27: =SUM('案件．要員情報'!O28:X28) -> 0.525 | P27: =SUM('案件．要員情報'!Y28:AH28) -> 0.0063492063 | Q27: =SUM('案件．要員情報'!AI28:AR28) -> 0 | R27: =SUM('案件．要員情報'!AS28:BB28) -> 0 | S27: =SUM('案件．要員情報'!BC28:BL28) -> 0 | T27: =SUM('案件．要員情報'!BM28:BV28) -> 0 | U27: =SUM('案件．要員情報'!BW28:CF28) -> 0 | V27: =SUM('案件．要員情報'!CG28:CP28) -> 0 | W27: =SUM('案件．要員情報'!CQ28:CW28) -> 0 | X27: =SUM('案件．要員情報'!CX28:DD28) -> 0 | Y27: =SUM('案件．要員情報'!DE28:DK28) -> 0 | Z27: =SUM('案件．要員情報'!DL28:DS28) -> 0 | AA27: =SUM(O27:Z27) -> 0.53134921
A28: 12 | B28: 完了 | C28: その他 | D28: 田中 | E28: AH21 | G28: 【ツール開発】HULFTログからの一覧作成 | N28: 計画 | O28: =SUM('案件．要員情報'!O29:X29) -> 0.091666667 | P28: =SUM('案件．要員情報'!Y29:AH29) -> 0 | Q28: =SUM('案件．要員情報'!AI29:AR29) -> 0 | R28: =SUM('案件．要員情報'!AS29:BB29) -> 0 | S28: =SUM('案件．要員情報'!BC29:BL29) -> 0 | T28: =SUM('案件．要員情報'!BM29:BV29) -> 0 | U28: =SUM('案件．要員情報'!BW29:CF29) -> 0 | V28: =SUM('案件．要員情報'!CG29:CP29) -> 0 | W28: =SUM('案件．要員情報'!CQ29:CW29) -> 0 | X28: =SUM('案件．要員情報'!CX29:DD29) -> 0 | Y28: =SUM('案件．要員情報'!DE29:DK29) -> 0 | Z28: =SUM('案件．要員情報'!DL29:DS29) -> 0 | AA28: =SUM(O28:Z28) -> 0.091666667
N29: 実績 | O29: =SUM('案件．要員情報'!O30:X30) -> 0.070833333 | P29: =SUM('案件．要員情報'!Y30:AH30) -> 0 | Q29: =SUM('案件．要員情報'!AI30:AR30) -> 0 | R29: =SUM('案件．要員情報'!AS30:BB30) -> 0 | S29: =SUM('案件．要員情報'!BC30:BL30) -> 0 | T29: =SUM('案件．要員情報'!BM30:BV30) -> 0 | U29: =SUM('案件．要員情報'!BW30:CF30) -> 0 | V29: =SUM('案件．要員情報'!CG30:CP30) -> 0 | W29: =SUM('案件．要員情報'!CQ30:CW30) -> 0 | X29: =SUM('案件．要員情報'!CX30:DD30) -> 0 | Y29: =SUM('案件．要員情報'!DE30:DK30) -> 0 | Z29: =SUM('案件．要員情報'!DL30:DS30) -> 0 | AA29: =SUM(O29:Z29) -> 0.070833333
A30: 13 | B30: 完了 | C30: その他 | D30: 安藤 | E30: WA1 | G30: 【WB4】【開発依頼】作業の自動化 | N30: 計画 | O30: =SUM('案件．要員情報'!O31:X31) -> 0 | P30: =SUM('案件．要員情報'!Y31:AH31) -> 0.47619048 | Q30: =SUM('案件．要員情報'!AI31:AR31) -> 0.20952381 | R30: =SUM('案件．要員情報'!AS31:BB31) -> 0 | S30: =SUM('案件．要員情報'!BC31:BL31) -> 0 | T30: =SUM('案件．要員情報'!BM31:BV31) -> 0 | U30: =SUM('案件．要員情報'!BW31:CF31) -> 0 | V30: =SUM('案件．要員情報'!CG31:CP31) -> 0 | W30: =SUM('案件．要員情報'!CQ31:CW31) -> 0 | X30: =SUM('案件．要員情報'!CX31:DD31) -> 0 | Y30: =SUM('案件．要員情報'!DE31:DK31) -> 0 | Z30: =SUM('案件．要員情報'!DL31:DS31) -> 0 | AA30: =SUM(O30:Z30) -> 0.68571429
N31: 実績 | O31: =SUM('案件．要員情報'!O32:X32) -> 0 | P31: =SUM('案件．要員情報'!Y32:AH32) -> 0.39365079 | Q31: =SUM('案件．要員情報'!AI32:AR32) -> 0.2031746 | R31: =SUM('案件．要員情報'!AS32:BB32) -> 0 | S31: =SUM('案件．要員情報'!BC32:BL32) -> 0 | T31: =SUM('案件．要員情報'!BM32:BV32) -> 0 | U31: =SUM('案件．要員情報'!BW32:CF32) -> 0 | V31: =SUM('案件．要員情報'!CG32:CP32) -> 0 | W31: =SUM('案件．要員情報'!CQ32:CW32) -> 0 | X31: =SUM('案件．要員情報'!CX32:DD32) -> 0 | Y31: =SUM('案件．要員情報'!DE32:DK32) -> 0 | Z31: =SUM('案件．要員情報'!DL32:DS32) -> 0 | AA31: =SUM(O31:Z31) -> 0.5968254
A32: 14 | B32: 完了 | C32: その他 | D32: 谷口 | E32: WT11 | G32: 【開発依頼】Windows11動作検証 | N32: 計画 | O32: =SUM('案件．要員情報'!O33:X33) -> 0 | P32: =SUM('案件．要員情報'!Y33:AH33) -> 0.6031746 | Q32: =SUM('案件．要員情報'!AI33:AR33) -> 3.2777778 | R32: =SUM('案件．要員情報'!AS33:BB33) -> 2.5333333 | S32: =SUM('案件．要員情報'!BC33:BL33) -> 3.3015873 | T32: =SUM('案件．要員情報'!BM33:BV33) -> 0 | U32: =SUM('案件．要員情報'!BW33:CF33) -> 0 | V32: =SUM('案件．要員情報'!CG33:CP33) -> 0 | W32: =SUM('案件．要員情報'!CQ33:CW33) -> 0 | X32: =SUM('案件．要員情報'!CX33:DD33) -> 0 | Y32: =SUM('案件．要員情報'!DE33:DK33) -> 0 | Z32: =SUM('案件．要員情報'!DL33:DS33) -> 0 | AA32: =SUM(O32:Z32) -> 9.715873
N33: 実績 | O33: =SUM('案件．要員情報'!O34:X34) -> 0 | P33: =SUM('案件．要員情報'!Y34:AH34) -> 0.58095238 | Q33: =SUM('案件．要員情報'!AI34:AR34) -> 3.2698413 | R33: =SUM('案件．要員情報'!AS34:BB34) -> 2.4575758 | S33: =SUM('案件．要員情報'!BC34:BL34) -> 3.2888889 | T33: =SUM('案件．要員情報'!BM34:BV34) -> 0 | U33: =SUM('案件．要員情報'!BW34:CF34) -> 0 | V33: =SUM('案件．要員情報'!CG34:CP34) -> 0 | W33: =SUM('案件．要員情報'!CQ34:CW34) -> 0 | X33: =SUM('案件．要員情報'!CX34:DD34) -> 0 | Y33: =SUM('案件．要員情報'!DE34:DK34) -> 0 | Z33: =SUM('案件．要員情報'!DL34:DS34) -> 0 | AA33: =SUM(O33:Z33) -> 9.5972583
A34: 15 | B34: 完了 | C34: その他 | D34: 仲井 | E34: BT1 | G34: 【全社】プリファレンステーブルの設定値最新化対応 | N34: 計画 | O34: =SUM('案件．要員情報'!O35:X35) -> 0 | P34: =SUM('案件．要員情報'!Y35:AH35) -> 0.63492063 | Q34: =SUM('案件．要員情報'!AI35:AR35) -> 1.2634921 | R34: =SUM('案件．要員情報'!AS35:BB35) -> 0.84848485 | S34: =SUM('案件．要員情報'!BC35:BL35) -> 1.8412698 | T34: =SUM('案件．要員情報'!BM35:BV35) -> 0 | U34: =SUM('案件．要員情報'!BW35:CF35) -> 0 | V34: =SUM('案件．要員情報'!CG35:CP35) -> 0 | W34: =SUM('案件．要員情報'!CQ35:CW35) -> 0 | X34: =SUM('案件．要員情報'!CX35:DD35) -> 0 | Y34: =SUM('案件．要員情報'!DE35:DK35) -> 0 | Z34: =SUM('案件．要員情報'!DL35:DS35) -> 0 | AA34: =SUM(O34:Z34) -> 4.5881674
N35: 実績 | O35: =SUM('案件．要員情報'!O36:X36) -> 0 | P35: =SUM('案件．要員情報'!Y36:AH36) -> 0.61269841 | Q35: =SUM('案件．要員情報'!AI36:AR36) -> 1.247619 | R35: =SUM('案件．要員情報'!AS36:BB36) -> 0.87575758 | S35: =SUM('案件．要員情報'!BC36:BL36) -> 1.7111111 | T35: =SUM('案件．要員情報'!BM36:BV36) -> 0 | U35: =SUM('案件．要員情報'!BW36:CF36) -> 0 | V35: =SUM('案件．要員情報'!CG36:CP36) -> 0 | W35: =SUM('案件．要員情報'!CQ36:CW36) -> 0 | X35: =SUM('案件．要員情報'!CX36:DD36) -> 0 | Y35: =SUM('案件．要員情報'!DE36:DK36) -> 0 | Z35: =SUM('案件．要員情報'!DL36:DS36) -> 0 | AA35: =SUM(O35:Z35) -> 4.4471861
A36: 16 | B36: 完了 | C36: その他 | D36: 山本 | E36: BT2 | G36: (44)注文失効件数チェック処理の改善_横展開 | N36: 計画 | O36: =SUM('案件．要員情報'!O37:X37) -> 0 | P36: =SUM('案件．要員情報'!Y37:AH37) -> 0.31746032 | Q36: =SUM('案件．要員情報'!AI37:AR37) -> 0.43180952 | R36: =SUM('案件．要員情報'!AS37:BB37) -> 0 | S36: =SUM('案件．要員情報'!BC37:BL37) -> 0 | T36: =SUM('案件．要員情報'!BM37:BV37) -> 0 | U36: =SUM('案件．要員情報'!BW37:CF37) -> 0 | V36: =SUM('案件．要員情報'!CG37:CP37) -> 0 | W36: =SUM('案件．要員情報'!CQ37:CW37) -> 0 | X36: =SUM('案件．要員情報'!CX37:DD37) -> 0 | Y36: =SUM('案件．要員情報'!DE37:DK37) -> 0 | Z36: =SUM('案件．要員情報'!DL37:DS37) -> 0 | AA36: =SUM(O36:Z36) -> 0.74926984
N37: 実績 | O37: =SUM('案件．要員情報'!O38:X38) -> 0 | P37: =SUM('案件．要員情報'!Y38:AH38) -> 0.27936508 | Q37: =SUM('案件．要員情報'!AI38:AR38) -> 0.42857143 | R37: =SUM('案件．要員情報'!AS38:BB38) -> 0 | S37: =SUM('案件．要員情報'!BC38:BL38) -> 0 | T37: =SUM('案件．要員情報'!BM38:BV38) -> 0 | U37: =SUM('案件．要員情報'!BW38:CF38) -> 0 | V37: =SUM('案件．要員情報'!CG38:CP38) -> 0 | W37: =SUM('案件．要員情報'!CQ38:CW38) -> 0 | X37: =SUM('案件．要員情報'!CX38:DD38) -> 0 | Y37: =SUM('案件．要員情報'!DE38:DK38) -> 0 | Z37: =SUM('案件．要員情報'!DL38:DS38) -> 0 | AA37: =SUM(O37:Z37) -> 0.70793651
A38: 17 | B38: 完了 | C38: その他 | D38: 寺澤 | E38: SFA6 | G38: 【SFA】画面文言変更対応のお願い | N38: 計画 | O38: =SUM('案件．要員情報'!O39:X39) -> 0 | P38: =SUM('案件．要員情報'!Y39:AH39) -> 0 | Q38: =SUM('案件．要員情報'!AI39:AR39) -> 0.36825397 | R38: =SUM('案件．要員情報'!AS39:BB39) -> 0 | S38: =SUM('案件．要員情報'!BC39:BL39) -> 0 | T38: =SUM('案件．要員情報'!BM39:BV39) -> 0 | U38: =SUM('案件．要員情報'!BW39:CF39) -> 0 | V38: =SUM('案件．要員情報'!CG39:CP39) -> 0 | W38: =SUM('案件．要員情報'!CQ39:CW39) -> 0 | X38: =SUM('案件．要員情報'!CX39:DD39) -> 0 | Y38: =SUM('案件．要員情報'!DE39:DK39) -> 0 | Z38: =SUM('案件．要員情報'!DL39:DS39) -> 0 | AA38: =SUM(O38:Z38) -> 0.36825397
N39: 実績 | O39: =SUM('案件．要員情報'!O40:X40) -> 0 | P39: =SUM('案件．要員情報'!Y40:AH40) -> 0 | Q39: =SUM('案件．要員情報'!AI40:AR40) -> 0.36507937 | R39: =SUM('案件．要員情報'!AS40:BB40) -> 0 | S39: =SUM('案件．要員情報'!BC40:BL40) -> 0 | T39: =SUM('案件．要員情報'!BM40:BV40) -> 0 | U39: =SUM('案件．要員情報'!BW40:CF40) -> 0 | V39: =SUM('案件．要員情報'!CG40:CP40) -> 0 | W39: =SUM('案件．要員情報'!CQ40:CW40) -> 0 | X39: =SUM('案件．要員情報'!CX40:DD40) -> 0 | Y39: =SUM('案件．要員情報'!DE40:DK40) -> 0 | Z39: =SUM('案件．要員情報'!DL40:DS40) -> 0 | AA39: =SUM(O39:Z39) -> 0.36507937
A40: 18 | B40: 完了 | C40: その他 | D40: 寺澤 | E40: SFA7 | G40: 【SFA】(000050)画面文言変更対応 | N40: 計画 | O40: =SUM('案件．要員情報'!O41:X41) -> 0 | P40: =SUM('案件．要員情報'!Y41:AH41) -> 0 | Q40: =SUM('案件．要員情報'!AI41:AR41) -> 1.0793651 | R40: =SUM('案件．要員情報'!AS41:BB41) -> 0.58181818 | S40: =SUM('案件．要員情報'!BC41:BL41) -> 0 | T40: =SUM('案件．要員情報'!BM41:BV41) -> 0 | U40: =SUM('案件．要員情報'!BW41:CF41) -> 0 | V40: =SUM('案件．要員情報'!CG41:CP41) -> 0 | W40: =SUM('案件．要員情報'!CQ41:CW41) -> 0 | X40: =SUM('案件．要員情報'!CX41:DD41) -> 0 | Y40: =SUM('案件．要員情報'!DE41:DK41) -> 0 | Z40: =SUM('案件．要員情報'!DL41:DS41) -> 0 | AA40: =SUM(O40:Z40) -> 1.6611833
...

Sheet 案件．要員情報
A1: 案件．要員情報 | P1: Total Member - 10 | S1: Contract Member - 8 | Z1: Total Member - 10 | AC1: Contract Member - 8 | AJ1: Total Member - 10 | AM1: Contract Member - 8 | AT1: Total Member - 8 | AW1: Contract Member - 7 | BD1: Total Member - 8 | BF1: Total Member - 8 | BI1: Contract Member - 7 | BN1: Total Member - 8 | BQ1: Contract Member - 7 | BX1: Total Member - 8 | CA1: Contract Member - 7 | CH1: Total Member - 8 | CK1: Contract Member - 7 | CR1: Total Member - 8 | CU1: Contract Member - 7 | CY1: Total Member - 8 | DB1: Contract Member - 7 | DF1: Total Member - 8 | DI1: Contract Member - 7 | DM1: Total Member - 8 | DP1: Contract Member - 7
P2: FOC Member - 2 | Z2: FOC Member - 2 | AJ2: FOC Member - 2 | AT2: FOC Member - 1 | BD2: FOC Member - 1 | BF2: FOC Member - 1 | BN2: FOC Member - 1 | BX2: FOC Member - 1 | CH2: FOC Member - 1 | CR2: FOC Member - 1 | CY2: FOC Member - 1 | DF2: FOC Member - 1 | DM2: FOC Member - 1
A3: ■案件
A4: No. | B4: ステータス | C4: 区分 | D4: DIR 担当 | E4: 案件管理コード（DAT) | F4: 案件管理コード（DIR) | G4: 案件 | H4: 計画 (DIR) | I4: 計画 (DAT) | J4: 進捗 （％） | K4: 着手日 | L4: 完了日 | M4: 備考 | N4: 工数（人月）
O5: 4月 | Y5: 5月 | AI5: 6月 | AS5: 7月 | BC5: 8月 | BM5: 9月 | BW5: 10月 | CG5: 11月 | CQ5: 12月 | CX5: 1月 | DE5: 2月 | DL5: 3月
O6: TZA | P6: AMTZ | Q6: TSO | R6: NCM | S6: IKK | T6: MMH | U6: KBN | V6: SMZK | W6: SYA | X6: MHS | Y6: TZA | Z6: AMTZ | AA6: TSO | AB6: NCM | AC6: IKK | AD6: MMH | AE6: KBN | AF6: SMZK | AG6: SYA | AH6: MHS | AI6: TZA | AJ6: AMTZ | AK6: TSO | AL6: NCM | AM6: IKK | AN6: MMH | AO6: KBN | AP6: SMZK | AQ6: SYA | AR6: MHS | AS6: TZA | AT6: AMTZ | AU6: TSO | AV6: NCM | AW6: IKK | AX6: MMH | AY6: KBN | AZ6: SMZK | BA6: SYA | BB6: MHS | BC6: TZA | BD6: AMTZ | BE6: TSO | BF6: NCM | BG6: IKK | BH6: MMH | BI6: KBN | BJ6: SMZK | BK6: SYA | BL6: MHS | BM6: TZA | BN6: AMTZ | BO6: TSO | BP6: NCM | BQ6: IKK | BR6: MMH | BS6: KBN | BT6: SMZK | BU6: SYA | BV6: MHS | BW6: TZA | BX6: AMTZ | BY6: TSO | BZ6: NCM | CA6: IKK | CB6: MMH | CC6: KBN | CD6: SMZK | CE6: SYA | CF6: MHS | CG6: TZA | CH6: AMTZ | CI6: TSO | CJ6: NCM | CK6: IKK | CL6: MMH | CM6: KBN | CN6: SMZK | CO6: SYA | CP6: MHS | CQ6: TZA | CR6: AMTZ | CS6: TSO | CT6: NCM | CU6: MMH | CV6: SMZK | CW6: SYA | CX6: TZA | CY6: AMTZ | CZ6: TSO | DA6: NCM | DB6: MMH | DC6: SMZK | DD6: SYA | DE6: TZA | DF6: AMTZ | DG6: TSO | DH6: NCM | DI6: MMH | DJ6: SMZK | DK6: SYA | DL6: TZA | DM6: HWY | DN6: SPH | DO6: KSH | DP6: TSO | DQ6: SNNT | DR6: IKK | DS6: KBN
A7: 1 | B7: 着手中 | C7: その他 | D7: 飯田 | E7: BW1 | F7: A5207110 | G7: 【案件依頼】ビルド作業を対応 | H7: =SUM(DE7:DK7) -> 0.47058824 | I7: =SUM(DE8:DK8) -> 0.24313725 | N7: 計画 | O7: =(0)/120 -> 0 | P7: =(0)/120 -> 0 | Q7: =(0)/120 -> 0 | R7: =(21)/120 -> 0.175 | S7: =(21)/120 -> 0.175 | T7: =(0)/120 -> 0 | U7: =(0)/120 -> 0 | V7: =(21)/120 -> 0.175 | W7: =(21)/120 -> 0.175 | X7: =(0)/120 -> 0 | Y7: =(0)/157.5 -> 0 | Z7: =(0)/157.5 -> 0 | AA7: =(10)/157.5 -> 0.063492063 | AB7: =(10)/157.5 -> 0.063492063 | AC7: =(10)/157.5 -> 0.063492063 | AD7: =(0)/157.5 -> 0 | AE7: =(10)/157.5 -> 0.063492063 | AF7: =(10)/157.5 -> 0.063492063 | AG7: =(20)/157.5 -> 0.12698413 | AH7: =(0)/157.5 -> 0 | AI7: =(0)/157.5 -> 0 | AJ7: =(0)/157.5 -> 0 | AK7: =(0)/157.5 -> 0 | AL7: =(12.4)/157.5 -> 0.078730159 | AM7: =(12.4)/157.5 -> 0.078730159 | AN7: =(0)/157.5 -> 0 | AO7: =(12.4)/157.5 -> 0.078730159 | AP7: =(12.4)/157.5 -> 0.078730159 | AQ7: =(12.4)/157.5 -> 0.078730159 | AR7: =(0)/157.5 -> 0 | AS7: =(0)/165 -> 0 | AT7: =(0)/165 -> 0 | AU7: =(12)/165 -> 0.072727273 | AV7: =(12)/165 -> 0.072727273 | AW7: =(10)/165 -> 0.060606061 | AX7: =(0)/165 -> 0 | AY7: =(12)/165 -> 0.072727273 | AZ7: =(12)/165 -> 0.072727273 | BA7: =(12)/165 -> 0.072727273 | BB7: =(0)/165 -> 0 | BC7: =(0)/157.5 -> 0 | BD7: =(0)/157.5 -> 0 | BE7: =(19)/157.5 -> 0.12063492 | BF7: =(10)/157.5 -> 0.063492063 | BG7: =(19)/157.5 -> 0.12063492 | BH7: =(0)/157.5 -> 0 | BI7: =(19)/157.5 -> 0.12063492 | BJ7: =(19)/157.5 -> 0.12063492 | BK7: =(19)/157.5 -> 0.12063492 | BL7: =(0)/157.5 -> 0 | BM7: =(0)/165 -> 0 | BN7: =(0)/165 -> 0 | BO7: =(10)/165 -> 0.060606061 | BP7: =(15)/165 -> 0.090909091 | BQ7: =(0)/165 -> 0 | BR7: =(15)/165 -> 0.090909091 | BS7: =(10)/165 -> 0.060606061 | BT7: =(10)/165 -> 0.060606061 | BU7: =(10)/165 -> 0.060606061 | BV7: =(0)/165 -> 0 | BW7: =(0)/150 -> 0 | BX7: =(0)/150 -> 0 | BY7: =(6)/150 -> 0.04 | BZ7: =(6)/150 -> 0.04 | CA7: =(6)/150 -> 0.04 | CB7: =(6)/150 -> 0.04 | CC7: =(12)/150 -> 0.08 | CD7: =(0)/150 -> 0 | CE7: =(12)/150 -> 0.08 | CF7: =(12)/150 -> 0.08 | CG7: =(0)/135 -> 0 | CH7: =(0)/135 -> 0 | CI7: =(10)/135 -> 0.074074074 | CJ7: =(0)/135 -> 0 | CK7: =(0)/135 -> 0 | CL7: =(10)/135 -> 0.074074074 | CM7: =(0)/135 -> 0 | CN7: =(10)/135 -> 0.074074074 | CO7: =(10)/135 -> 0.074074074 | CP7: =(0)/135 -> 0 | CQ7: =(0)/150 -> 0 | CR7: =(0)/150 -> 0 | CS7: =(0)/150 -> 0 | CT7: =(10)/150 -> 0.066666667 | CU7: =(10)/150 -> 0.066666667 | CV7: =(10)/150 -> 0.066666667 | CW7: =(5)/150 -> 0.033333333 | CX7: =(0)/157.5 -> 0 | CY7: =(15)/157.5 -> 0.095238095 | CZ7: =(0)/157.5 -> 0 | DA7: =(10)/157.5 -> 0.063492063 | DB7: =(10)/157.5 -> 0.063492063 | DC7: =(10)/157.5 -> 0.063492063 | DD7: =(0)/157.5 -> 0 | DE7: =(0)/127.5 -> 0 | DF7: =(10)/127.5 -> 0.078431373 | DG7: =(10)/127.5 -> 0.078431373 | DH7: =(10)/127.5 -> 0.078431373 | DI7: =(10)/127.5 -> 0.078431373 | DJ7: =(10)/127.5 -> 0.078431373 | DK7: =(10)/127.5 -> 0.078431373 | DL7: =0/142.5 -> 0 | DM7: =0/142.5 -> 0 | DN7: =0/142.5 -> 0 | DO7: =0/142.5 -> 0 | DP7: =0/142.5 -> 0 | DQ7: =0/172.5 -> 0 | DR7: =0/172.5 -> 0 | DS7: =0/172.5 -> 0
N8: 実績 | O8: =(0)/120 -> 0 | P8: =(0)/120 -> 0 | Q8: =(0)/120 -> 0 | R8: =(0+6+4+6)/120 -> 0.13333333 | S8: =(5+7+2+4)/120 -> 0.15 | T8: =(0)/120 -> 0 | U8: =(0)/120 -> 0 | V8: =(5+5+5.5+2)/120 -> 0.14583333 | W8: =(0+9+5+12)/120 -> 0.21666667 | X8: =(0)/120 -> 0 | Y8: =(0)/157.5 -> 0 | Z8: =(0)/157.5 -> 0 | AA8: =(0+5)/157.5 -> 0.031746032 | AB8: =(2)/157.5 -> 0.012698413 | AC8: =(6+3)/157.5 -> 0.057142857 | AD8: =(0)/157.5 -> 0 | AE8: =(4+6+4)/157.5 -> 0.088888889 | AF8: =(2+6+4.5)/157.5 -> 0.079365079 | AG8: =(3+5+7+4+2)/157.5 -> 0.13333333 | AH8: =(0)/157.5 -> 0 | AI8: =(0)/157.5 -> 0 | AJ8: =(0)/157.5 -> 0 | AK8: =(0)/157.5 -> 0 | AL8: =(0+6+4)/157.5 -> 0.063492063 | AM8: =(6+3.5+5+5)/157.5 -> 0.12380952 | AN8: =(0)/157.5 -> 0 | AO8: =(0+6+4)/157.5 -> 0.063492063 | AP8: =(0+4+4)/157.5 -> 0.050793651 | AQ8: =(0+6+4+2)/157.5 -> 0.076190476 | AR8: =(0)/157.5 -> 0 | AS8: =(0)/165 -> 0 | AT8: =(0)/165 -> 0 | AU8: =(2+3+3+1)/165 -> 0.054545455 | AV8: =(4+4+4+4)/165 -> 0.096969697 | AW8: =(0+4+2)/165 -> 0.036363636 | AX8: =(0)/165 -> 0 | AY8: =(0+4+6+2)/165 -> 0.072727273 | AZ8: =(0+4+3)/165 -> 0.042424242 | BA8: =(3+2+5+4)/165 -> 0.084848485 | BB8: =(0)/165 -> 0 | BC8: =(0)/157.5 -> 0 | BD8: =(0)/157.5 -> 0 | BE8: =(1+13+8)/157.5 -> 0.13968254 | BF8: =(2+5)/157.5 -> 0.044444444 | BG8: =(5+11+4)/157.5 -> 0.12698413 | BH8: =(0)/157.5 -> 0 | BI8: =(9+6)/157.5 -> 0.095238095 | BJ8: =(8+5+9+6)/157.5 -> 0.17777778 | BK8: =(6+6)/157.5 -> 0.076190476 | BL8: =(0)/157.5 -> 0 | BM8: =(0)/165 -> 0 | BN8: =(0)/165 -> 0 | BO8: =(0+3.5)/165 -> 0.021212121 | BP8: =(8.5+5.5)/165 -> 0.084848485 | BQ8: =(0)/165 -> 0 | BR8: =(6+6+3)/165 -> 0.090909091 | BS8: =(6+4)/165 -> 0.060606061 | BT8: =(6+4+2)/165 -> 0.072727273 | BU8: =(0+6)/165 -> 0.036363636 | BV8: =(0)/165 -> 0 | BW8: =(0)/150 -> 0 | BX8: =(0)/150 -> 0 | BY8: =(3.5+4)/150 -> 0.05 | BZ8: =(0+6+4)/150 -> 0.066666667 | CA8: =(0+3+3)/150 -> 0.04 | CB8: =(0+3)/150 -> 0.02 | CC8: =(0+6+4)/150 -> 0.066666667 | CD8: =(0)/150 -> 0 | CE8: =(3+6+1)/150 -> 0.066666667 | CF8: =(0+8+5)/150 -> 0.086666667 | CG8: =(0)/135 -> 0 | CH8: =(0)/135 -> 0 | CI8: =(0+4+3.5)/135 -> 0.055555556 | CJ8: =(0)/135 -> 0 | CK8: =(0)/135 -> 0 | CL8: =(6)/135 -> 0.044444444 | CM8: =(0)/135 -> 0 | CN8: =(6)/135 -> 0.044444444 | CO8: =(0+5+5)/135 -> 0.074074074 | CP8: =(0)/135 -> 0 | CQ8: =(0)/150 -> 0 | CR8: =(0)/150 -> 0 | CS8: =(0)/150 -> 0 | CT8: =(6+2)/150 -> 0.053333333 | CU8: =(0+2+6)/150 -> 0.053333333 | CV8: =(6+4)/150 -> 0.066666667 | CW8: =(0+6)/150 -> 0.04 | CX8: =(0)/157.5 -> 0 | CY8: =(10.5+5)/157.5 -> 0.098412698 | CZ8: =(0)/157.5 -> 0 | DA8: =(0+6+4)/157.5 -> 0.063492063 | DB8: =(6)/157.5 -> 0.038095238 | DC8: =(0+6+4)/157.5 -> 0.063492063 | DD8: =(0)/157.5 -> 0 | DE8: =(0)/127.5 -> 0 | DF8: =(0+2.5+5.5)/127.5 -> 0.062745098 | DG8: =(0+2+4)/127.5 -> 0.047058824 | DH8: =(0)/127.5 -> 0 | DI8: =(6+4)/127.5 -> 0.078431373 | DJ8: =(0)/127.5 -> 0 | DK8: =(4+3)/127.5 -> 0.054901961 | DL8: =0/142.5 -> 0 | DM8: =0/142.5 -> 0 | DN8: =0/142.5 -> 0 | DO8: =0/142.5 -> 0 | DP8: =0/142.5 -> 0 | DQ8: =0/172.5 -> 0 | DR8: =0/172.5 -> 0 | DS8: =0/172.5 -> 0
A9: 2 | B9: 完了 | C9: その他 | D9: 坂野 | E9: PL6 | F9: PBxxxxxxxx | G9: 【PLATE】対面WEB_初期フォーカス改善対応 | H9: =SUM(Y9:AH9) -> 0 | I9: =SUM(Y10:AH10) -> 0 | N9: 計画 | O9: =(0)/120 -> 0 | P9: =(0)/120 -> 0 | Q9: =(0)/120 -> 0 | R9: =(0)/120 -> 0 | S9: =(0)/120 -> 0 | T9: =(0)/120 -> 0 | U9: =(0)/120 -> 0 | V9: =(0)/120 -> 0 | ... X9: =(0)/120 -> 0 | Y9: =(0)/157.5 -> 0 | Z9: =(0)/157.5 -> 0 | AA9: =(0)/157.5 -> 0 | AB9: =(0)/157.5 -> 0 | AC9: =(0)/157.5 -> 0 | AD9: =(0)/157.5 -> 0 | AE9: =(0)/157.5 -> 0 | AF9: =(0)/157.5 -> 0 | ... AH9: =(0)/157.5 -> 0 | AI9: =0/165 -> 0 | AJ9: =0/165 -> 0 | AK9: =0/165 -> 0 | AL9: =0/165 -> 0 | AM9: =0/165 -> 0 | AN9: =0/165 -> 0 | AO9: =0/165 -> 0 | AP9: =0/165 -> 0 | ... AR9: =0/165 -> 0 | AS9: =0/157.5 -> 0 | AT9: =0/157.5 -> 0 | AU9: =0/157.5 -> 0 | AV9: =0/157.5 -> 0 | AW9: =0/157.5 -> 0 | AX9: =0/165 -> 0 | AY9: =0/165 -> 0 | AZ9: =0/165 -> 0 | BA9: =0/165 -> 0 | BB9: =0/165 -> 0 | BC9: =0/157.5 -> 0 | BD9: =0/157.5 -> 0 | BE9: =0/157.5 -> 0 | BF9: =0/157.5 -> 0 | BG9: =0/157.5 -> 0 | BH9: =0/157.5 -> 0 | BI9: =0/157.5 -> 0 | BJ9: =0/165 -> 0 | BK9: =0/165 -> 0 | BL9: =0/165 -> 0 | BM9: =0/172.5 -> 0 | BN9: =0/172.5 -> 0 | BO9: =0/172.5 -> 0 | BP9: =0/172.5 -> 0 | BQ9: =0/172.5 -> 0 | BR9: =0/172.5 -> 0 | BS9: =0/172.5 -> 0 | BV9: =0/172.5 -> 0 | BW9: =0/142.5 -> 0 | BX9: =(0)/165 -> 0 | BY9: =(0)/165 -> 0 | BZ9: =(0)/165 -> 0 | CA9: =(0)/165 -> 0 | CB9: =(0)/165 -> 0 | CC9: =(0)/165 -> 0 | CD9: =(0)/165 -> 0 | CE9: =(0)/165 -> 0 | CF9: =(0)/165 -> 0 | CG9: =0/142.5 -> 0 | CH9: =0/142.5 -> 0 | CI9: =0/142.5 -> 0 | CJ9: =0/142.5 -> 0 | CK9: =0/142.5 -> 0 | CL9: =0/172.5 -> 0 | CM9: =0/172.5 -> 0 | CN9: =0/172.5 -> 0 | CO9: =0/172.5 -> 0 | CP9: =0/172.5 -> 0 | CQ9: =0/157.5 -> 0 | CR9: =0/157.5 -> 0 | CS9: =0/157.5 -> 0 | CT9: =0/157.5 -> 0 | CU9: =0/157.5 -> 0 | CV9: =0/172.5 -> 0 | CW9: =0/172.5 -> 0 | CX9: =0/157.5 -> 0 | CY9: =0/157.5 -> 0 | CZ9: =0/157.5 -> 0 | DA9: =0/157.5 -> 0 | DB9: =0/157.5 -> 0 | DC9: =0/172.5 -> 0 | DD9: =0/172.5 -> 0 | DE9: =0/127.5 -> 0 | DF9: =0/127.5 -> 0 | DG9: =0/127.5 -> 0 | DH9: =0/127.5 -> 0 | DI9: =0/127.5 -> 0 | DJ9: =0/172.5 -> 0 | DK9: =0/172.5 -> 0 | DL9: =0/142.5 -> 0 | DM9: =0/142.5 -> 0 | DN9: =0/142.5 -> 0 | DO9: =0/142.5 -> 0 | DP9: =0/142.5 -> 0 | DQ9: =0/172.5 -> 0 | DR9: =0/172.5 -> 0 | DS9: =0/172.5 -> 0
N10: 実績 | O10: =(0)/120 -> 0 | P10: =(0)/120 -> 0 | Q10: =(0)/120 -> 0 | R10: =(0)/120 -> 0 | S10: =(0)/120 -> 0 | T10: =(0)/120 -> 0 | U10: =(0)/120 -> 0 | V10: =(0)/120 -> 0 | ... X10: =(0)/120 -> 0 | Y10: =(0)/157.5 -> 0 | Z10: =(0)/157.5 -> 0 | AA10: =(0)/157.5 -> 0 | AB10: =(0)/157.5 -> 0 | AC10: =(0)/157.5 -> 0 | AD10: =(0)/157.5 -> 0 | AE10: =(0)/157.5 -> 0 | AF10: =(0)/157.5 -> 0 | ... AH10: =(0)/157.5 -> 0 | AI10: =0/165 -> 0 | AJ10: =0/165 -> 0 | AK10: =0/165 -> 0 | AL10: =0/165 -> 0 | AM10: =0/165 -> 0 | AN10: =0/165 -> 0 | AO10: =0/165 -> 0 | AP10: =0/165 -> 0 | ... AR10: =0/165 -> 0 | AS10: =0/157.5 -> 0 | AT10: =0/157.5 -> 0 | AU10: =0/157.5 -> 0 | AV10: =0/157.5 -> 0 | AW10: =0/157.5 -> 0 | AX10: =0/165 -> 0 | AY10: =0/165 -> 0 | AZ10: =0/165 -> 0 | BA10: =0/165 -> 0 | BB10: =0/165 -> 0 | BC10: =0/157.5 -> 0 | BD10: =0/157.5 -> 0 | BE10: =0/157.5 -> 0 | BF10: =0/157.5 -> 0 | BG10: =0/157.5 -> 0 | BH10: =0/157.5 -> 0 | BI10: =0/157.5 -> 0 | BJ10: =0/165 -> 0 | BK10: =0/165 -> 0 | BL10: =0/165 -> 0 | BM10: =0/172.5 -> 0 | BN10: =0/172.5 -> 0 | BO10: =0/172.5 -> 0 | BP10: =0/172.5 -> 0 | BQ10: =0/172.5 -> 0 | BR10: =0/172.5 -> 0 | BS10: =0/172.5 -> 0 | BV10: =0/172.5 -> 0 | BW10: =0/142.5 -> 0 | BX10: =(0)/165 -> 0 | BY10: =(0)/165 -> 0 | BZ10: =(0)/165 -> 0 | CA10: =(0)/165 -> 0 | CB10: =(0)/165 -> 0 | CC10: =(0)/165 -> 0 | CD10: =(0)/165 -> 0 | CE10: =(0)/165 -> 0 | CF10: =(0)/165 -> 0 | CG10: =0/142.5 -> 0 | CH10: =0/142.5 -> 0 | CI10: =0/142.5 -> 0 | CJ10: =0/142.5 -> 0 | CK10: =0/142.5 -> 0 | CL10: =0/172.5 -> 0 | CM10: =0/172.5 -> 0 | CN10: =0/172.5 -> 0 | CO10: =0/172.5 -> 0 | CP10: =0/172.5 -> 0 | CQ10: =0/157.5 -> 0 | CR10: =0/157.5 -> 0 | CS10: =0/157.5 -> 0 | CT10: =0/157.5 -> 0 | CU10: =0/157.5 -> 0 | CV10: =0/172.5 -> 0 | CW10: =0/172.5 -> 0 | CX10: =0/157.5 -> 0 | CY10: =0/157.5 -> 0 | CZ10: =0/157.5 -> 0 | DA10: =0/157.5 -> 0 | DB10: =0/157.5 -> 0 | DC10: =0/172.5 -> 0 | DD10: =0/172.5 -> 0 | DE10: =0/127.5 -> 0 | DF10: =0/127.5 -> 0 | DG10: =0/127.5 -> 0 | DH10: =0/127.5 -> 0 | DI10: =0/127.5 -> 0 | DJ10: =0/172.5 -> 0 | DK10: =0/172.5 -> 0 | DL10: =0/142.5 -> 0 | DM10: =0/142.5 -> 0 | DN10: =0/142.5 -> 0 | DO10: =0/142.5 -> 0 | DP10: =0/142.5 -> 0 | DQ10: =0/172.5 -> 0 | DR10: =0/172.5 -> 0 | DS10: =0/172.5 -> 0
A11: 3 | B11: 完了 | C11: その他 | D11: 山本 | E11: WA2 | G11: 【開発依頼】作業の自動化_UATヘルスチェック | H11: =SUM(CG11:CP11) -> 0 | I11: =SUM(CG12:CP12) -> 0 | N11: 計画 | O11: =(0)/120 -> 0 | P11: =(0)/120 -> 0 | Q11: =(39.25)/120 -> 0.32708333 | R11: =(39.25)/120 -> 0.32708333 | S11: =(0)/120 -> 0 | T11: =(0)/120 -> 0 | U11: =(39.25)/120 -> 0.32708333 | V11: =(0)/120 -> 0 | W11: =(39.25)/120 -> 0.32708333 | X11: =(0)/120 -> 0 | Y11: =(30)/157.5 -> 0.19047619 | Z11: =(30)/157.5 -> 0.19047619 | AA11: =(30)/157.5 -> 0.19047619 | AB11: =(0)/157.5 -> 0 | AC11: =(30)/157.5 -> 0.19047619 | AD11: =(30)/157.5 -> 0.19047619 | AE11: =(60)/157.5 -> 0.38095238 | AF11: =(30)/157.5 -> 0.19047619 | AG11: =(70)/157.5 -> 0.44444444 | AH11: =(0)/157.5 -> 0 | AI11: =(0)/157.5 -> 0 | AJ11: =(0)/157.5 -> 0 | AK11: =(0)/157.5 -> 0 | AL11: =(0)/157.5 -> 0 | AM11: =(0)/157.5 -> 0 | AN11: =(0)/157.5 -> 0 | AO11: =(0)/157.5 -> 0 | AP11: =(0)/157.5 -> 0 | AQ11: =(3)/157.5 -> 0.019047619 | AR11: =(0)/157.5 -> 0 | AS11: =(0)/165 -> 0 | AT11: =(0)/165 -> 0 | AU11: =(37.5)/165 -> 0.22727273 | AV11: =(0)/165 -> 0 | AW11: =(0)/165 -> 0 | AX11: =(0)/165 -> 0 | AY11: =(0)/165 -> 0 | AZ11: =(0)/165 -> 0 | BA11: =(37.5)/165 -> 0.22727273 | BB11: =(0)/165 -> 0 | BC11: =(0)/157.5 -> 0 | BD11: =(0)/157.5 -> 0 | BE11: =(22.5)/157.5 -> 0.14285714 | BF11: =(0)/157.5 -> 0 | BG11: =(0)/157.5 -> 0 | BH11: =(0)/157.5 -> 0 | BI11: =(0)/157.5 -> 0 | BJ11: =(0)/157.5 -> 0 | BK11: =(22.5)/157.5 -> 0.14285714 | BL11: =(0)/157.5 -> 0 | BM11: =(0)/165 -> 0 | BN11: =(0)/165 -> 0 | BO11: =(50)/165 -> 0.3030303 | BP11: =(0)/165 -> 0 | BQ11: =(0)/165 -> 0 | BR11: =(0)/165 -> 0 | BS11: =(0)/165 -> 0 | BT11: =(0)/165 -> 0 | BU11: =(50)/165 -> 0.3030303 | BV11: =(0)/165 -> 0 | BW11: =(0)/150 -> 0 | BX11: =(0)/150 -> 0 | BY11: =(12)/150 -> 0.08 | BZ11: =(12)/150 -> 0.08 | CA11: =(0)/150 -> 0 | CB11: =(0)/150 -> 0 | CC11: =(0)/150 -> 0 | CD11: =(0)/150 -> 0 | CE11: =(21)/150 -> 0.14 | CF11: =(0)/150 -> 0 | CG11: =(0)/135 -> 0 | CH11: =(0)/135 -> 0 | CI11: =(0)/135 -> 0 | CJ11: =(0)/135 -> 0 | CK11: =(0)/135 -> 0 | CL11: =(0)/135 -> 0 | CM11: =(0)/135 -> 0 | CN11: =(0)/135 -> 0 | ... CP11: =(0)/135 -> 0 | CQ11: =0/157.5 -> 0 | CR11: =0/157.5 -> 0 | CS11: =0/157.5 -> 0 | CT11: =0/157.5 -> 0 | CU11: =0/157.5 -> 0 | CV11: =0/172.5 -> 0 | CW11: =0/172.5 -> 0 | CX11: =0/157.5 -> 0 | CY11: =0/157.5 -> 0 | CZ11: =0/157.5 -> 0 | DA11: =0/157.5 -> 0 | DB11: =0/157.5 -> 0 | DC11: =0/172.5 -> 0 | DD11: =0/172.5 -> 0 | DE11: =0/127.5 -> 0 | DF11: =0/127.5 -> 0 | DG11: =0/127.5 -> 0 | DH11: =0/127.5 -> 0 | DI11: =0/127.5 -> 0 | DJ11: =0/172.5 -> 0 | DK11: =0/172.5 -> 0 | DL11: =0/142.5 -> 0 | DM11: =0/142.5 -> 0 | DN11: =0/142.5 -> 0 | DO11: =0/142.5 -> 0 | DP11: =0/142.5 -> 0 | DQ11: =0/172.5 -> 0 | DR11: =0/172.5 -> 0 | DS11: =0/172.5 -> 0
N12: 実績 | O12: =(0)/120 -> 0 | P12: =(0)/120 -> 0 | Q12: =(0+7+13.5+7+28)/120 -> 0.4625 | R12: =(0+5)/120 -> 0.041666667 | S12: =(0)/120 -> 0 | T12: =(0)/120 -> 0 | U12: =(0+12+14+14+33)/120 -> 0.60833333 | V12: =(0)/120 -> 0 | W12: =(19)/120 -> 0.15833333 | X12: =(0)/120 -> 0 | Y12: =(0+1.5+2.5+11.5)/157.5 -> 0.098412698 | Z12: =(0+12+3.5)/157.5 -> 0.098412698 | AA12: =(17+15+24.5+34.5)/157.5 -> 0.57777778 | AB12: =(0)/157.5 -> 0 | AC12: =(0+15+5.5)/157.5 -> 0.13015873 | AD12: =(0+5+4.5)/157.5 -> 0.06031746 | AE12: =(17.5+8+21.5+18.5)/157.5 -> 0.41587302 | AF12: =(0+15)/157.5 -> 0.095238095 | AG12: =(18+21+14+19.5+2)/157.5 -> 0.47301587 | AH12: =(0)/157.5 -> 0 | AI12: =(0)/157.5 -> 0 | AJ12: =(0)/157.5 -> 0 | AK12: =(0)/157.5 -> 0 | AL12: =(0)/157.5 -> 0 | AM12: =(0)/157.5 -> 0 | AN12: =(0)/157.5 -> 0 | AO12: =(0)/157.5 -> 0 | AP12: =(0)/157.5 -> 0 | AQ12: =(0+2.5)/157.5 -> 0.015873016 | AR12: =(0)/157.5 -> 0 | AS12: =(0)/165 -> 0 | AT12: =(0)/165 -> 0 | AU12: =(6+6+7+14.5+2)/165 -> 0.21515152 | AV12: =(0)/165 -> 0 | AW12: =(0)/165 -> 0 | AX12: =(0)/165 -> 0 | AY12: =(0)/165 -> 0 | AZ12: =(0)/165 -> 0 | BA12: =(3+8.5+8+8+6+3)/165 -> 0.22121212 | BB12: =(0)/165 -> 0 | BC12: =(0)/157.5 -> 0 | BD12: =(0)/157.5 -> 0 | BE12: =(13+3+5)/157.5 -> 0.13333333 | BF12: =(0)/157.5 -> 0 | BG12: =(0)/157.5 -> 0 | BH12: =(0)/157.5 -> 0 | BI12: =(0)/157.5 -> 0 | BJ12: =(0)/157.5 -> 0 | BK12: =(13.5+6.5)/157.5 -> 0.12698413 | BL12: =(0)/157.5 -> 0 | BM12: =(1+5.5+8.5)/165 -> 0.090909091 | BN12: =(0)/165 -> 0 | BO12: =(9+17+6.5)/165 -> 0.1969697 | BP12: =(0)/165 -> 0 | BQ12: =(0)/165 -> 0 | BR12: =(0)/165 -> 0 | BS12: =(0)/165 -> 0 | BT12: =(0)/165 -> 0 | BU12: =(11.5+33+10)/165 -> 0.33030303 | BV12: =(0)/165 -> 0 | BW12: =(0)/150 -> 0 | BX12: =(0)/150 -> 0 | BY12: =(0+3.5+9)/150 -> 0.083333333 | BZ12: =(0+9.5)/150 -> 0.063333333 | CA12: =(0)/150 -> 0 | CB12: =(0)/150 -> 0 | CC12: =(0)/150 -> 0 | CD12: =(0)/150 -> 0 | CE12: =(0+5+14+2)/150 -> 0.14 | CF12: =(0)/150 -> 0 | CG12: =(0)/135 -> 0 | CH12: =(0)/135 -> 0 | CI12: =(0)/135 -> 0 | CJ12: =(0)/135 -> 0 | CK12: =(0)/135 -> 0 | CL12: =(0)/135 -> 0 | CM12: =(0)/135 -> 0 | CN12: =(0)/135 -> 0 | ... CP12: =(0)/135 -> 0 | CQ12: =0/157.5 -> 0 | CR12: =0/157.5 -> 0 | CS12: =0/157.5 -> 0 | CT12: =0/157.5 -> 0 | CU12: =0/157.5 -> 0 | CV12: =0/172.5 -> 0 | CW12: =0/172.5 -> 0 | CX12: =0/157.5 -> 0 | CY12: =0/157.5 -> 0 | CZ12: =0/157.5 -> 0 | DA12: =0/157.5 -> 0 | DB12: =0/157.5 -> 0 | DC12: =0/172.5 -> 0 | DD12: =0/172.5 -> 0 | DE12: =0/127.5 -> 0 | DF12: =0/127.5 -> 0 | DG12: =0/127.5 -> 0 | DH12: =0/127.5 -> 0 | DI12: =0/127.5 -> 0 | DJ12: =0/172.5 -> 0 | DK12: =0/172.5 -> 0 | DL12: =0/142.5 -> 0 | DM12: =0/142.5 -> 0 | DN12: =0/142.5 -> 0 | DO12: =0/142.5 -> 0 | DP12: =0/142.5 -> 0 | DQ12: =0/172.5 -> 0 | DR12: =0/172.5 -> 0 | DS12: =0/172.5 -> 0
A13: 4 | B13: 完了 | C13: 定型 | D13: 山本 | E13: F180 | F13: PB00201841 | G13: 【定型】定時定額の注文画面での文言追加 | H13: =SUM(CG13:CP13) -> 0 | I13: =SUM(CG14:CP14) -> 0 | N13: 計画 | O13: =(0)/120 -> 0 | P13: =(9)/120 -> 0.075 | Q13: =(0)/120 -> 0 | R13: =(9)/120 -> 0.075 | S13: =(0)/120 -> 0 | T13: =(0)/120 -> 0 | U13: =(0)/120 -> 0 | V13: =(0)/120 -> 0 | W13: =(0)/120 -> 0 | X13: =(0)/120 -> 0 | Y13: =(0)/157.5 -> 0 | Z13: =(0)/157.5 -> 0 | AA13: =(0)/157.5 -> 0 | AB13: =(0)/157.5 -> 0 | AC13: =(0)/157.5 -> 0 | AD13: =(0)/157.5 -> 0 | AE13: =(0)/157.5 -> 0 | AF13: =(0)/157.5 -> 0 | ... AR13: =(0)/157.5 -> 0 | AS13: =(0)/165 -> 0 | AT13: =(0)/165 -> 0 | AU13: =(0)/165 -> 0 | AV13: =(0)/165 -> 0 | AW13: =(0)/165 -> 0 | AX13: =(0)/165 -> 0 | AY13: =(0)/165 -> 0 | AZ13: =(0)/165 -> 0 | ... BB13: =(0)/165 -> 0 | BC13: =(0)/157.5 -> 0 | BD13: =(0)/157.5 -> 0 | BE13: =(0)/157.5 -> 0 | BF13: =(0)/157.5 -> 0 | BG13: =(0)/157.5 -> 0 | BH13: =(0)/157.5 -> 0 | BI13: =(0)/157.5 -> 0 | BJ13: =(0)/157.5 -> 0 | ... BL13: =(0)/157.5 -> 0 | BM13: =(0)/165 -> 0 | BN13: =(0)/165 -> 0 | BO13: =(0)/165 -> 0 | BP13: =(0)/165 -> 0 | BQ13: =(0)/165 -> 0 | BR13: =(0)/165 -> 0 | BS13: =(0)/165 -> 0 | BT13: =(0)/165 -> 0 | ... BV13: =(0)/165 -> 0 | BW13: =(0)/150 -> 0 | BX13: =(0)/150 -> 0 | BY13: =(0)/150 -> 0 | BZ13: =(0)/150 -> 0 | CA13: =(0)/150 -> 0 | CB13: =(0)/150 -> 0 | CC13: =(0)/150 -> 0 | CD13: =(0)/150 -> 0 | ... CF13: =(0)/150 -> 0 | CG13: =(0)/135 -> 0 | CH13: =(0)/135 -> 0 | CI13: =(0)/135 -> 0 | CJ13: =(0)/135 -> 0 | CK13: =(0)/135 -> 0 | CL13: =(0)/135 -> 0 | CM13: =(0)/135 -> 0 | CN13: =(0)/135 -> 0 | ... CP13: =(0)/135 -> 0 | CQ13: =0/157.5 -> 0 | CR13: =0/157.5 -> 0 | CS13: =0/157.5 -> 0 | CT13: =0/157.5 -> 0 | CU13: =0/157.5 -> 0 | CV13: =0/172.5 -> 0 | CW13: =0/172.5 -> 0 | CX13: =0/157.5 -> 0 | CY13: =0/157.5 -> 0 | CZ13: =0/157.5 -> 0 | DA13: =0/157.5 -> 0 | DB13: =0/157.5 -> 0 | DC13: =0/172.5 -> 0 | DD13: =0/172.5 -> 0 | DE13: =0/127.5 -> 0 | DF13: =0/127.5 -> 0 | DG13: =0/127.5 -> 0 | DH13: =0/127.5 -> 0 | DI13: =0/127.5 -> 0 | DJ13: =0/172.5 -> 0 | DK13: =0/172.5 -> 0 | DL13: =0/142.5 -> 0 | DM13: =0/142.5 -> 0 | DN13: =0/142.5 -> 0 | DO13: =0/142.5 -> 0 | DP13: =0/142.5 -> 0 | DQ13: =0/172.5 -> 0 | DR13: =0/172.5 -> 0 | DS13: =0/172.5 -> 0
N14: 実績 | O14: =(0)/120 -> 0 | P14: =(0.5+1)/120 -> 0.0125 | Q14: =(0)/120 -> 0 | R14: =(14+1.5)/120 -> 0.12916667 | S14: =(0)/120 -> 0 | T14: =(0)/120 -> 0 | U14: =(0)/120 -> 0 | V14: =(0)/120 -> 0 | W14: =(0)/120 -> 0 | X14: =(0)/120 -> 0 | Y14: =(0)/157.5 -> 0 | Z14: =(0)/157.5 -> 0 | AA14: =(0)/157.5 -> 0 | AB14: =(0)/157.5 -> 0 | AC14: =(0)/157.5 -> 0 | AD14: =(0)/157.5 -> 0 | AE14: =(0)/157.5 -> 0 | AF14: =(0)/157.5 -> 0 | ... AR14: =(0)/157.5 -> 0 | AS14: =(0)/165 -> 0 | AT14: =(0)/165 -> 0 | AU14: =(0)/165 -> 0 | AV14: =(0)/165 -> 0 | AW14: =(0)/165 -> 0 | AX14: =(0)/165 -> 0 | AY14: =(0)/165 -> 0 | AZ14: =(0)/165 -> 0 | ... BB14: =(0)/165 -> 0 | BC14: =(0)/157.5 -> 0 | BD14: =(0)/157.5 -> 0 | BE14: =(0)/157.5 -> 0 | BF14: =(0)/157.5 -> 0 | BG14: =(0)/157.5 -> 0 | BH14: =(0)/157.5 -> 0 | BI14: =(0)/157.5 -> 0 | BJ14: =(0)/157.5 -> 0 | ... BL14: =(0)/157.5 -> 0 | BM14: =(0)/165 -> 0 | BN14: =(0)/165 -> 0 | BO14: =(0)/165 -> 0 | BP14: =(0)/165 -> 0 | BQ14: =(0)/165 -> 0 | BR14: =(0)/165 -> 0 | BS14: =(0)/165 -> 0 | BT14: =(0)/165 -> 0 | ... BV14: =(0)/165 -> 0 | BW14: =(0)/150 -> 0 | BX14: =(0)/150 -> 0 | BY14: =(0)/150 -> 0 | BZ14: =(0)/150 -> 0 | CA14: =(0)/150 -> 0 | CB14: =(0)/150 -> 0 | CC14: =(0)/150 -> 0 | CD14: =(0)/150 -> 0 | ... CF14: =(0)/150 -> 0 | CG14: =(0)/135 -> 0 | CH14: =(0)/135 -> 0 | CI14: =(0)/135 -> 0 | CJ14: =(0)/135 -> 0 | CK14: =(0)/135 -> 0 | CL14: =(0)/135 -> 0 | CM14: =(0)/135 -> 0 | CN14: =(0)/135 -> 0 | ... CP14: =(0)/135 -> 0 | CQ14: =0/157.5 -> 0 | CR14: =0/157.5 -> 0 | CS14: =0/157.5 -> 0 | CT14: =0/157.5 -> 0 | CU14: =0/157.5 -> 0 | CV14: =0/172.5 -> 0 | CW14: =0/172.5 -> 0 | CX14: =0/157.5 -> 0 | CY14: =0/157.5 -> 0 | CZ14: =0/157.5 -> 0 | DA14: =0/157.5 -> 0 | DB14: =0/157.5 -> 0 | DC14: =0/172.5 -> 0 | DD14: =0/172.5 -> 0 | DE14: =0/127.5 -> 0 | DF14: =0/127.5 -> 0 | DG14: =0/127.5 -> 0 | DH14: =0/127.5 -> 0 | DI14: =0/127.5 -> 0 | DJ14: =0/172.5 -> 0 | DK14: =0/172.5 -> 0 | DL14: =0/142.5 -> 0 | DM14: =0/142.5 -> 0 | DN14: =0/142.5 -> 0 | DO14: =0/142.5 -> 0 | DP14: =0/142.5 -> 0 | DQ14: =0/172.5 -> 0 | DR14: =0/172.5 -> 0 | DS14: =0/172.5 -> 0
A15: 5 | B15: 完了 | C15: 定型 | D15: 山田 | E15: F181 | F15: PB00201845 | G15: 【定型】CFDサービス終了に伴う画面修正 | H15: =SUM(CG15:CP15) -> 0 | I15: =SUM(CG16:CP16) -> 0 | N15: 計画 | O15: =(0)/120 -> 0 | P15: =(5)/120 -> 0.041666667 | Q15: =(0)/120 -> 0 | R15: =(0)/120 -> 0 | S15: =(15)/120 -> 0.125 | T15: =(15)/120 -> 0.125 | U15: =(0)/120 -> 0 | V15: =(0)/120 -> 0 | W15: =(0)/120 -> 0 | X15: =(0)/120 -> 0 | Y15: =(0)/157.5 -> 0 | Z15: =(0)/157.5 -> 0 | AA15: =(0)/157.5 -> 0 | AB15: =(0)/157.5 -> 0 | AC15: =(0)/157.5 -> 0 | AD15: =(0)/157.5 -> 0 | AE15: =(0)/157.5 -> 0 | AF15: =(0)/157.5 -> 0 | ... AR15: =(0)/157.5 -> 0 | AS15: =(0)/165 -> 0 | AT15: =(0)/165 -> 0 | AU15: =(0)/165 -> 0 | AV15: =(0)/165 -> 0 | AW15: =(0)/165 -> 0 | AX15: =(0)/165 -> 0 | AY15: =(0)/165 -> 0 | AZ15: =(0)/165 -> 0 | ... BB15: =(0)/165 -> 0 | BC15: =(0)/157.5 -> 0 | BD15: =(0)/157.5 -> 0 | BE15: =(0)/157.5 -> 0 | BF15: =(0)/157.5 -> 0 | BG15: =(0)/157.5 -> 0 | BH15: =(0)/157.5 -> 0 | BI15: =(0)/157.5 -> 0 | BJ15: =(0)/157.5 -> 0 | ... BL15: =(0)/157.5 -> 0 | BM15: =(0)/165 -> 0 | BN15: =(0)/165 -> 0 | BO15: =(0)/165 -> 0 | BP15: =(0)/165 -> 0 | BQ15: =(0)/165 -> 0 | BR15: =(0)/165 -> 0 | BS15: =(0)/165 -> 0 | BT15: =(0)/165 -> 0 | ... BV15: =(0)/165 -> 0 | BW15: =(0)/150 -> 0 | BX15: =(0)/150 -> 0 | BY15: =(0)/150 -> 0 | BZ15: =(0)/150 -> 0 | CA15: =(0)/150 -> 0 | CB15: =(0)/150 -> 0 | CC15: =(0)/150 -> 0 | CD15: =(0)/150 -> 0 | ... CF15: =(0)/150 -> 0 | CG15: =(0)/135 -> 0 | CH15: =(0)/135 -> 0 | CI15: =(0)/135 -> 0 | CJ15: =(0)/135 -> 0 | CK15: =(0)/135 -> 0 | CL15: =(0)/135 -> 0 | CM15: =(0)/135 -> 0 | CN15: =(0)/135 -> 0 | ... CP15: =(0)/135 -> 0 | CQ15: =0/157.5 -> 0 | CR15: =0/157.5 -> 0 | CS15: =0/157.5 -> 0 | CT15: =0/157.5 -> 0 | CU15: =0/157.5 -> 0 | CV15: =0/172.5 -> 0 | CW15: =0/172.5 -> 0 | CX15: =0/157.5 -> 0 | CY15: =0/157.5 -> 0 | CZ15: =0/157.5 -> 0 | DA15: =0/157.5 -> 0 | DB15: =0/157.5 -> 0 | DC15: =0/172.5 -> 0 | DD15: =0/172.5 -> 0 | DE15: =0/127.5 -> 0 | DF15: =0/127.5 -> 0 | DG15: =0/127.5 -> 0 | DH15: =0/127.5 -> 0 | DI15: =0/127.5 -> 0 | DJ15: =0/172.5 -> 0 | DK15: =0/172.5 -> 0 | DL15: =0/142.5 -> 0 | DM15: =0/142.5 -> 0 | DN15: =0/142.5 -> 0 | DO15: =0/142.5 -> 0 | DP15: =0/142.5 -> 0 | DQ15: =0/172.5 -> 0 | DR15: =0/172.5 -> 0 | DS15: =0/172.5 -> 0
N16: 実績 | O16: =(0)/120 -> 0 | P16: =(0.5+3+1)/120 -> 0.0375 | Q16: =(0)/120 -> 0 | R16: =(0)/120 -> 0 | S16: =(5+9.5)/120 -> 0.12083333 | T16: =(12+3)/120 -> 0.125 | U16: =(0)/120 -> 0 | V16: =(0)/120 -> 0 | W16: =(0)/120 -> 0 | X16: =(0)/120 -> 0 | Y16: =(0)/157.5 -> 0 | Z16: =(0)/157.5 -> 0 | AA16: =(0)/157.5 -> 0 | AB16: =(0)/157.5 -> 0 | AC16: =(0)/157.5 -> 0 | AD16: =(0)/157.5 -> 0 | AE16: =(0)/157.5 -> 0 | AF16: =(0)/157.5 -> 0 | ... AR16: =(0)/157.5 -> 0 | AS16: =(0)/165 -> 0 | AT16: =(0)/165 -> 0 | AU16: =(0)/165 -> 0 | AV16: =(0)/165 -> 0 | AW16: =(0)/165 -> 0 | AX16: =(0)/165 -> 0 | AY16: =(0)/165 -> 0 | AZ16: =(0)/165 -> 0 | ... BB16: =(0)/165 -> 0 | BC16: =(0)/157.5 -> 0 | BD16: =(0)/157.5 -> 0 | BE16: =(0)/157.5 -> 0 | BF16: =(0)/157.5 -> 0 | BG16: =(0)/157.5 -> 0 | BH16: =(0)/157.5 -> 0 | BI16: =(0)/157.5 -> 0 | BJ16: =(0)/157.5 -> 0 | ... BL16: =(0)/157.5 -> 0 | BM16: =(0)/165 -> 0 | BN16: =(0)/165 -> 0 | BO16: =(0)/165 -> 0 | BP16: =(0)/165 -> 0 | BQ16: =(0)/165 -> 0 | BR16: =(0)/165 -> 0 | BS16: =(0)/165 -> 0 | BT16: =(0)/165 -> 0 | ... BV16: =(0)/165 -> 0 | BW16: =(0)/150 -> 0 | BX16: =(0)/150 -> 0 | BY16: =(0)/150 -> 0 | BZ16: =(0)/150 -> 0 | CA16: =(0)/150 -> 0 | CB16: =(0)/150 -> 0 | CC16: =(0)/150 -> 0 | CD16: =(0)/150 -> 0 | ... CF16: =(0)/150 -> 0 | CG16: =(0)/135 -> 0 | CH16: =(0)/135 -> 0 | CI16: =(0)/135 -> 0 | CJ16: =(0)/135 -> 0 | CK16: =(0)/135 -> 0 | CL16: =(0)/135 -> 0 | CM16: =(0)/135 -> 0 | CN16: =(0)/135 -> 0 | ... CP16: =(0)/135 -> 0 | CQ16: =0/157.5 -> 0 | CR16: =0/157.5 -> 0 | CS16: =0/157.5 -> 0 | CT16: =0/157.5 -> 0 | CU16: =0/157.5 -> 0 | CV16: =0/172.5 -> 0 | CW16: =0/172.5 -> 0 | CX16: =0/157.5 -> 0 | CY16: =0/157.5 -> 0 | CZ16: =0/157.5 -> 0 | DA16: =0/157.5 -> 0 | DB16: =0/157.5 -> 0 | DC16: =0/172.5 -> 0 | DD16: =0/172.5 -> 0 | DE16: =0/127.5 -> 0 | DF16: =0/127.5 -> 0 | DG16: =0/127.5 -> 0 | DH16: =0/127.5 -> 0 | DI16: =0/127.5 -> 0 | DJ16: =0/172.5 -> 0 | DK16: =0/172.5 -> 0 | DL16: =0/142.5 -> 0 | DM16: =0/142.5 -> 0 | DN16: =0/142.5 -> 0 | DO16: =0/142.5 -> 0 | DP16: =0/142.5 -> 0 | DQ16: =0/172.5 -> 0 | DR16: =0/172.5 -> 0 | DS16: =0/172.5 -> 0
A17: 6 | B17: 完了 | C17: 定型 | D17: 山田 | E17: F182 | F17: PB00201860 | G17: 【定型】WB4ログイン画面ロゴ画像の変更 | H17: =SUM(CG17:CP17) -> 0 | I17: =SUM(CG18:CP18) -> 0 | N17: 計画 | O17: =(0)/120 -> 0 | P17: =(20)/120 -> 0.16666667 | Q17: =(0)/120 -> 0 | R17: =(0)/120 -> 0 | S17: =(5)/120 -> 0.041666667 | T17: =(20)/120 -> 0.16666667 | U17: =(5)/120 -> 0.041666667 | V17: =(20)/120 -> 0.16666667 | W17: =(20)/120 -> 0.16666667 | X17: =(5)/120 -> 0.041666667 | Y17: =(0)/157.5 -> 0 | Z17: =(0)/157.5 -> 0 | AA17: =(0)/157.5 -> 0 | AB17: =(0)/157.5 -> 0 | AC17: =(0)/157.5 -> 0 | AD17: =(0)/157.5 -> 0 | AE17: =(0)/157.5 -> 0 | AF17: =(0)/157.5 -> 0 | ... AR17: =(0)/157.5 -> 0 | AS17: =(0)/165 -> 0 | AT17: =(0)/165 -> 0 | AU17: =(0)/165 -> 0 | AV17: =(0)/165 -> 0 | AW17: =(0)/165 -> 0 | AX17: =(0)/165 -> 0 | AY17: =(0)/165 -> 0 | AZ17: =(0)/165 -> 0 | ... BB17: =(0)/165 -> 0 | BC17: =(0)/157.5 -> 0 | BD17: =(0)/157.5 -> 0 | BE17: =(0)/157.5 -> 0 | BF17: =(0)/157.5 -> 0 | BG17: =(0)/157.5 -> 0 | BH17: =(0)/157.5 -> 0 | BI17: =(0)/157.5 -> 0 | BJ17: =(0)/157.5 -> 0 | ... BL17: =(0)/157.5 -> 0 | BM17: =(0)/165 -> 0 | BN17: =(0)/165 -> 0 | BO17: =(0)/165 -> 0 | BP17: =(0)/165 -> 0 | BQ17: =(0)/165 -> 0 | BR17: =(0)/165 -> 0 | BS17: =(0)/165 -> 0 | BT17: =(0)/165 -> 0 | ... BV17: =(0)/165 -> 0 | BW17: =(0)/150 -> 0 | BX17: =(0)/150 -> 0 | BY17: =(0)/150 -> 0 | BZ17: =(0)/150 -> 0 | CA17: =(0)/150 -> 0 | CB17: =(0)/150 -> 0 | CC17: =(0)/150 -> 0 | CD17: =(0)/150 -> 0 | ... CF17: =(0)/150 -> 0 | CG17: =(0)/135 -> 0 | CH17: =(0)/135 -> 0 | CI17: =(0)/135 -> 0 | CJ17: =(0)/135 -> 0 | CK17: =(0)/135 -> 0 | CL17: =(0)/135 -> 0 | CM17: =(0)/135 -> 0 | CN17: =(0)/135 -> 0 | ... CP17: =(0)/135 -> 0 | CQ17: =0/157.5 -> 0 | CR17: =0/157.5 -> 0 | CS17: =0/157.5 -> 0 | CT17: =0/157.5 -> 0 | CU17: =0/157.5 -> 0 | CV17: =0/172.5 -> 0 | CW17: =0/172.5 -> 0 | CX17: =0/157.5 -> 0 | CY17: =0/157.5 -> 0 | CZ17: =0/157.5 -> 0 | DA17: =0/157.5 -> 0 | DB17: =0/157.5 -> 0 | DC17: =0/172.5 -> 0 | DD17: =0/172.5 -> 0 | DE17: =0/127.5 -> 0 | DF17: =0/127.5 -> 0 | DG17: =0/127.5 -> 0 | DH17: =0/127.5 -> 0 | DI17: =0/127.5 -> 0 | DJ17: =0/172.5 -> 0 | DK17: =0/172.5 -> 0 | DL17: =0/142.5 -> 0 | DM17: =0/142.5 -> 0 | DN17: =0/142.5 -> 0 | DO17: =0/142.5 -> 0 | DP17: =0/142.5 -> 0 | DQ17: =0/172.5 -> 0 | DR17: =0/172.5 -> 0 | DS17: =0/172.5 -> 0
N18: 実績 | O18: =(0)/120 -> 0 | P18: =(11.5+1+1+2.5)/120 -> 0.13333333 | Q18: =(0)/120 -> 0 | R18: =(0)/120 -> 0 | S18: =(4)/120 -> 0.033333333 | T18: =(13.5+2+1)/120 -> 0.1375 | U18: =(10)/120 -> 0.083333333 | V18: =(8.5+8.5+3)/120 -> 0.16666667 | W18: =(13.5)/120 -> 0.1125 | X18: =(13.5)/120 -> 0.1125 | Y18: =(0)/157.5 -> 0 | Z18: =(0)/157.5 -> 0 | AA18: =(0)/157.5 -> 0 | AB18: =(0)/157.5 -> 0 | AC18: =(0)/157.5 -> 0 | AD18: =(0)/157.5 -> 0 | AE18: =(0)/157.5 -> 0 | AF18: =(0)/157.5 -> 0 | ... AR18: =(0)/157.5 -> 0 | AS18: =(0)/165 -> 0 | AT18: =(0)/165 -> 0 | AU18: =(0)/165 -> 0 | AV18: =(0)/165 -> 0 | AW18: =(0)/165 -> 0 | AX18: =(0)/165 -> 0 | AY18: =(0)/165 -> 0 | AZ18: =(0)/165 -> 0 | ... BB18: =(0)/165 -> 0 | BC18: =(0)/157.5 -> 0 | BD18: =(0)/157.5 -> 0 | BE18: =(0)/157.5 -> 0 | BF18: =(0)/157.5 -> 0 | BG18: =(0)/157.5 -> 0 | BH18: =(0)/157.5 -> 0 | BI18: =(0)/157.5 -> 0 | BJ18: =(0)/157.5 -> 0 | ... BL18: =(0)/157.5 -> 0 | BM18: =(0)/165 -> 0 | BN18: =(0)/165 -> 0 | BO18: =(0)/165 -> 0 | BP18: =(0)/165 -> 0 | BQ18: =(0)/165 -> 0 | BR18: =(0)/165 -> 0 | BS18: =(0)/165 -> 0 | BT18: =(0)/165 -> 0 | ... BV18: =(0)/165 -> 0 | BW18: =(0)/150 -> 0 | BX18: =(0)/150 -> 0 | BY18: =(0)/150 -> 0 | BZ18: =(0)/150 -> 0 | CA18: =(0)/150 -> 0 | CB18: =(0)/150 -> 0 | CC18: =(0)/150 -> 0 | CD18: =(0)/150 -> 0 | ... CF18: =(0)/150 -> 0 | CG18: =(0)/135 -> 0 | CH18: =(0)/135 -> 0 | CI18: =(0)/135 -> 0 | CJ18: =(0)/135 -> 0 | CK18: =(0)/135 -> 0 | CL18: =(0)/135 -> 0 | CM18: =(0)/135 -> 0 | CN18: =(0)/135 -> 0 | ... CP18: =(0)/135 -> 0 | CQ18: =0/157.5 -> 0 | CR18: =0/157.5 -> 0 | CS18: =0/157.5 -> 0 | CT18: =0/157.5 -> 0 | CU18: =0/157.5 -> 0 | CV18: =0/172.5 -> 0 | CW18: =0/172.5 -> 0 | CX18: =0/157.5 -> 0 | CY18: =0/157.5 -> 0 | CZ18: =0/157.5 -> 0 | DA18: =0/157.5 -> 0 | DB18: =0/157.5 -> 0 | DC18: =0/172.5 -> 0 | DD18: =0/172.5 -> 0 | DE18: =0/127.5 -> 0 | DF18: =0/127.5 -> 0 | DG18: =0/127.5 -> 0 | DH18: =0/127.5 -> 0 | DI18: =0/127.5 -> 0 | DJ18: =0/172.5 -> 0 | DK18: =0/172.5 -> 0 | DL18: =0/142.5 -> 0 | DM18: =0/142.5 -> 0 | DN18: =0/142.5 -> 0 | DO18: =0/142.5 -> 0 | DP18: =0/142.5 -> 0 | DQ18: =0/172.5 -> 0 | DR18: =0/172.5 -> 0 | DS18: =0/172.5 -> 0
A19: 7 | B19: 完了 | C19: その他 | D19: 寺澤 | E19: MSC1 | G19: 【MSC】画面設計書最新化対応のお願い | H19: =SUM(CG19:CP19) -> 0 | I19: =SUM(CG20:CP20) -> 0 | N19: 計画 | O19: =(0)/120 -> 0 | P19: =(20)/120 -> 0.16666667 | Q19: =(20)/120 -> 0.16666667 | R19: =(0)/120 -> 0 | S19: =(0)/120 -> 0 | T19: =(20)/120 -> 0.16666667 | U19: =(5)/120 -> 0.041666667 | V19: =(5)/120 -> 0.041666667 | W19: =(5)/120 -> 0.041666667 | X19: =(10)/120 -> 0.083333333 | Y19: =(0)/157.5 -> 0 | Z19: =(0)/157.5 -> 0 | AA19: =(0)/157.5 -> 0 | AB19: =(0)/157.5 -> 0 | AC19: =(0)/157.5 -> 0 | AD19: =(0)/157.5 -> 0 | AE19: =(0)/157.5 -> 0 | AF19: =(0)/157.5 -> 0 | ... AR19: =(0)/157.5 -> 0 | AS19: =(0)/165 -> 0 | AT19: =(0)/165 -> 0 | AU19: =(0)/165 -> 0 | AV19: =(0)/165 -> 0 | AW19: =(0)/165 -> 0 | AX19: =(0)/165 -> 0 | AY19: =(0)/165 -> 0 | AZ19: =(0)/165 -> 0 | ... BB19: =(0)/165 -> 0 | BC19: =(0)/157.5 -> 0 | BD19: =(0)/157.5 -> 0 | BE19: =(0)/157.5 -> 0 | BF19: =(0)/157.5 -> 0 | BG19: =(0)/157.5 -> 0 | BH19: =(0)/157.5 -> 0 | BI19: =(0)/157.5 -> 0 | BJ19: =(0)/157.5 -> 0 | ... BL19: =(0)/157.5 -> 0 | BM19: =(0)/165 -> 0 | BN19: =(0)/165 -> 0 | BO19: =(0)/165 -> 0 | BP19: =(0)/165 -> 0 | BQ19: =(0)/165 -> 0 | BR19: =(0)/165 -> 0 | BS19: =(0)/165 -> 0 | BT19: =(0)/165 -> 0 | ... BV19: =(0)/165 -> 0 | BW19: =(0)/150 -> 0 | BX19: =(0)/150 -> 0 | BY19: =(0)/150 -> 0 | BZ19: =(0)/150 -> 0 | CA19: =(0)/150 -> 0 | CB19: =(0)/150 -> 0 | CC19: =(0)/150 -> 0 | CD19: =(0)/150 -> 0 | ... CF19: =(0)/150 -> 0 | CG19: =(0)/135 -> 0 | CH19: =(0)/135 -> 0 | CI19: =(0)/135 -> 0 | CJ19: =(0)/135 -> 0 | CK19: =(0)/135 -> 0 | CL19: =(0)/135 -> 0 | CM19: =(0)/135 -> 0 | CN19: =(0)/135 -> 0 | ... CP19: =(0)/135 -> 0 | CQ19: =0/157.5 -> 0 | CR19: =0/157.5 -> 0 | CS19: =0/157.5 -> 0 | CT19: =0/157.5 -> 0 | CU19: =0/157.5 -> 0 | CV19: =0/172.5 -> 0 | CW19: =0/172.5 -> 0 | CX19: =0/157.5 -> 0 | CY19: =0/157.5 -> 0 | CZ19: =0/157.5 -> 0 | DA19: =0/157.5 -> 0 | DB19: =0/157.5 -> 0 | DC19: =0/172.5 -> 0 | DD19: =0/172.5 -> 0 | DE19: =0/127.5 -> 0 | DF19: =0/127.5 -> 0 | DG19: =0/127.5 -> 0 | DH19: =0/127.5 -> 0 | DI19: =0/127.5 -> 0 | DJ19: =0/172.5 -> 0 | DK19: =0/172.5 -> 0 | DL19: =0/142.5 -> 0 | DM19: =0/142.5 -> 0 | DN19: =0/142.5 -> 0 | DO19: =0/142.5 -> 0 | DP19: =0/142.5 -> 0 | DQ19: =0/172.5 -> 0 | DR19: =0/172.5 -> 0 | DS19: =0/172.5 -> 0
N20: 実績 | O20: =(0)/120 -> 0 | P20: =(13)/120 -> 0.10833333 | Q20: =(14)/120 -> 0.11666667 | R20: =(0)/120 -> 0 | S20: =(0)/120 -> 0 | T20: =(14)/120 -> 0.11666667 | U20: =(6.5)/120 -> 0.054166667 | V20: =(8)/120 -> 0.066666667 | W20: =(14)/120 -> 0.11666667 | X20: =(14)/120 -> 0.11666667 | Y20: =(0)/157.5 -> 0 | Z20: =(0)/157.5 -> 0 | AA20: =(0)/157.5 -> 0 | AB20: =(0)/157.5 -> 0 | AC20: =(0)/157.5 -> 0 | AD20: =(0)/157.5 -> 0 | AE20: =(0)/157.5 -> 0 | AF20: =(0)/157.5 -> 0 | ... AR20: =(0)/157.5 -> 0 | AS20: =(0)/165 -> 0 | AT20: =(0)/165 -> 0 | AU20: =(0)/165 -> 0 | AV20: =(0)/165 -> 0 | AW20: =(0)/165 -> 0 | AX20: =(0)/165 -> 0 | AY20: =(0)/165 -> 0 | AZ20: =(0)/165 -> 0 | ... BB20: =(0)/165 -> 0 | BC20: =(0)/157.5 -> 0 | BD20: =(0)/157.5 -> 0 | BE20: =(0)/157.5 -> 0 | BF20: =(0)/157.5 -> 0 | BG20: =(0)/157.5 -> 0 | BH20: =(0)/157.5 -> 0 | BI20: =(0)/157.5 -> 0 | BJ20: =(0)/157.5 -> 0 | ... BL20: =(0)/157.5 -> 0 | BM20: =(0)/165 -> 0 | BN20: =(0)/165 -> 0 | BO20: =(0)/165 -> 0 | BP20: =(0)/165 -> 0 | BQ20: =(0)/165 -> 0 | BR20: =(0)/165 -> 0 | BS20: =(0)/165 -> 0 | BT20: =(0)/165 -> 0 | ... BV20: =(0)/165 -> 0 | BW20: =(0)/150 -> 0 | BX20: =(0)/150 -> 0 | BY20: =(0)/150 -> 0 | BZ20: =(0)/150 -> 0 | CA20: =(0)/150 -> 0 | CB20: =(0)/150 -> 0 | CC20: =(0)/150 -> 0 | CD20: =(0)/150 -> 0 | ... CF20: =(0)/150 -> 0 | CG20: =(0)/135 -> 0 | CH20: =(0)/135 -> 0 | CI20: =(0)/135 -> 0 | CJ20: =(0)/135 -> 0 | CK20: =(0)/135 -> 0 | CL20: =(0)/135 -> 0 | CM20: =(0)/135 -> 0 | CN20: =(0)/135 -> 0 | ... CP20: =(0)/135 -> 0 | CQ20: =0/157.5 -> 0 | CR20: =0/157.5 -> 0 | CS20: =0/157.5 -> 0 | CT20: =0/157.5 -> 0 | CU20: =0/157.5 -> 0 | CV20: =0/172.5 -> 0 | CW20: =0/172.5 -> 0 | CX20: =0/157.5 -> 0 | CY20: =0/157.5 -> 0 | CZ20: =0/157.5 -> 0 | DA20: =0/157.5 -> 0 | DB20: =0/157.5 -> 0 | DC20: =0/172.5 -> 0 | DD20: =0/172.5 -> 0 | DE20: =0/127.5 -> 0 | DF20: =0/127.5 -> 0 | DG20: =0/127.5 -> 0 | DH20: =0/127.5 -> 0 | DI20: =0/127.5 -> 0 | DJ20: =0/172.5 -> 0 | DK20: =0/172.5 -> 0 | DL20: =0/142.5 -> 0 | DM20: =0/142.5 -> 0 | DN20: =0/142.5 -> 0 | DO20: =0/142.5 -> 0 | DP20: =0/142.5 -> 0 | DQ20: =0/172.5 -> 0 | DR20: =0/172.5 -> 0 | DS20: =0/172.5 -> 0
